Updating at:2019-04-28 15:38:14.182155
New Reviews found:{}
Updating at:2019-04-28 15:40:13.371269
New Reviews found:{}
Updating at: 2019-04-28 15:42:13.890543
New Reviews found: {}
Updating at: 2019-04-28 15:44:13.794180
New Reviews found: {}
Updating at: 2019-04-28 15:46:14.567569
New Reviews found: {}
Updating at: 2019-04-28 15:48:13.493572
New Reviews found: {}
Updating at: 2019-04-28 15:50:12.984409
New Reviews found: {}
Updating at: 2019-04-28 15:52:14.961713
New Reviews found: {}
Updating at: 2019-04-28 15:54:12.477329
New Reviews found: {}
Updating at: 2019-04-28 15:56:12.736524
New Reviews found: {}
Updating at: 2019-04-28 15:58:13.903638
New Reviews found: {}
Updating at: 2019-04-28 16:00:13.414607
New Reviews found: {}
Updating at: 2019-04-28 16:02:13.160917
New Reviews found: {}
Updating at: 2019-04-28 16:04:14.419302
New Reviews found: {}
Updating at: 2019-04-28 16:06:13.432934
New Reviews found: {}
Updating at: 2019-04-28 16:08:12.809266
New Reviews found: {}
Updating at: 2019-04-28 16:10:14.107869
New Reviews found: {}
Updating at: 2019-04-28 16:12:14.435774
New Reviews found: {}
Updating at: 2019-04-28 16:14:13.224166
New Reviews found: {}
Updating at: 2019-04-28 16:16:15.111446
New Reviews found: {}
Updating at: 2019-04-28 16:18:13.120886
New Reviews found: {}
Updating at: 2019-04-28 16:20:13.592922
New Reviews found: {}
Updating at: 2019-04-28 16:22:13.855647
New Reviews found: {}
Updating at: 2019-04-28 16:24:13.443827
New Reviews found: {}
Updating at: 2019-04-28 16:26:13.832969
New Reviews found: {}
Updating at: 2019-04-28 16:28:13.564896
New Reviews found: {}
Updating at: 2019-04-28 16:30:14.364771
New Reviews found: {}
Updating at: 2019-04-28 16:32:13.090336
New Reviews found: {}
Updating at: 2019-04-28 16:34:14.588462
New Reviews found: {}
Updating at: 2019-04-28 16:36:13.975246
New Reviews found: {}
Updating at: 2019-04-28 16:38:12.548334
New Reviews found: {}
Updating at: 2019-04-28 16:40:14.981496
New Reviews found: {}
Updating at: 2019-04-28 16:42:13.425809
New Reviews found: {}
Updating at: 2019-04-28 16:44:14.817679
New Reviews found: {}
Updating at: 2019-04-28 16:46:16.402492
New Reviews found: {}
Updating at: 2019-04-28 16:48:14.065739
New Reviews found: {}
Updating at: 2019-04-28 16:50:13.782735
New Reviews found: {}
Updating at: 2019-04-28 16:52:13.925402
New Reviews found: {}
Updating at: 2019-04-28 16:54:15.219754
New Reviews found: {}
Updating at: 2019-04-28 16:56:13.593198
New Reviews found: {}
Updating at: 2019-04-28 16:58:13.717187
New Reviews found: {}
Updating at: 2019-04-28 17:00:14.177271
New Reviews found: {}
Updating at: 2019-04-28 17:02:14.198436
New Reviews found: {}
Updating at: 2019-04-28 17:04:14.375274
New Reviews found: {}
Updating at: 2019-04-28 17:06:14.255173
New Reviews found: {}
Updating at: 2019-04-28 17:08:13.670936
New Reviews found: {}
Updating at: 2019-04-28 17:10:14.887073
New Reviews found: {}
Updating at: 2019-04-28 17:12:15.244084
New Reviews found: {}
Updating at: 2019-04-28 17:14:13.571040
New Reviews found: {}
Updating at: 2019-04-28 17:16:14.066069
New Reviews found: {}
Updating at: 2019-04-28 17:18:13.935928
New Reviews found: {}
Updating at: 2019-04-28 17:20:15.268684
New Reviews found: {}
Updating at: 2019-04-28 17:22:13.632572
New Reviews found: {}
Updating at: 2019-04-28 17:24:14.412256
New Reviews found: {}
Updating at: 2019-04-28 17:26:14.515759
New Reviews found: {}
Updating at: 2019-04-28 17:28:15.166404
New Reviews found: {}
Updating at: 2019-04-28 17:30:16.540455
New Reviews found: {}
Updating at: 2019-04-28 17:32:15.054389
New Reviews found: {}
Updating at: 2019-04-28 17:34:15.268632
New Reviews found: {}
Updating at: 2019-04-28 17:36:13.238511
New Reviews found: {}
Updating at: 2019-04-28 17:38:13.980243
New Reviews found: {}
Updating at: 2019-04-28 17:40:13.868847
New Reviews found: {}
Updating at: 2019-04-28 17:42:14.676398
New Reviews found: {}
Updating at: 2019-04-28 17:44:14.422331
New Reviews found: {}
Updating at: 2019-04-28 17:46:14.902762
New Reviews found: {}
Updating at: 2019-04-28 17:48:15.089317
New Reviews found: {}
Updating at: 2019-04-28 17:50:14.709051
New Reviews found: {}
Updating at: 2019-04-28 17:52:14.979591
New Reviews found: {}
Updating at: 2019-04-28 17:54:13.769488
New Reviews found: {}
Updating at: 2019-04-28 17:56:18.457638
New Reviews found: {}
Updating at: 2019-04-28 17:58:14.793125
New Reviews found: {}
Updating at: 2019-04-28 18:00:15.637288
New Reviews found: {}
Updating at: 2019-04-28 18:02:14.324882
New Reviews found: {}
Updating at: 2019-04-28 18:04:14.275462
New Reviews found: {}
Updating at: 2019-04-28 18:06:14.884473
New Reviews found: {}
Updating at: 2019-04-28 18:08:14.975146
New Reviews found: {}
Updating at: 2019-04-28 18:10:14.542436
New Reviews found: {}
Updating at: 2019-04-28 18:12:14.669874
New Reviews found: {}
Updating at: 2019-04-28 18:14:12.772678
New Reviews found: {}
Updating at: 2019-04-28 18:16:15.055289
New Reviews found: {}
Updating at: 2019-04-28 18:18:13.919432
New Reviews found: {}
Updating at: 2019-04-28 18:20:14.127336
New Reviews found: {}
Updating at: 2019-04-28 18:22:14.335116
New Reviews found: {}
Updating at: 2019-04-28 18:24:03.044445
New Reviews found: {}
Updating at: 2019-04-28 18:26:03.263513
New Reviews found: {}
Updating at: 2019-04-28 18:28:03.421401
New Reviews found: {}
Updating at: 2019-04-28 18:30:03.849607
New Reviews found: {}
Updating at: 2019-04-28 18:32:03.045383
New Reviews found: {}
Updating at: 2019-04-28 18:34:03.226178
New Reviews found: {}
Updating at: 2019-04-28 18:36:03.458175
New Reviews found: {}
Updating at: 2019-04-28 18:38:03.688815
New Reviews found: {}
Updating at: 2019-04-28 18:40:02.886992
New Reviews found: {}
Updating at: 2019-04-28 18:42:03.201650
New Reviews found: {}
Updating at: 2019-04-28 18:44:03.366647
New Reviews found: {}
Updating at: 2019-04-28 18:46:03.605624
New Reviews found: {}
Updating at: 2019-04-28 18:48:02.757799
New Reviews found: {}
Updating at: 2019-04-28 18:50:03.104015
New Reviews found: {}
Updating at: 2019-04-28 18:52:03.347929
New Reviews found: {}
Updating at: 2019-04-28 18:54:03.670120
New Reviews found: {}
Updating at: 2019-04-28 18:56:02.890525
New Reviews found: {}
Updating at: 2019-04-28 18:58:03.102049
New Reviews found: {}
Updating at: 2019-04-28 19:00:03.324109
New Reviews found: {}
Updating at: 2019-04-28 19:02:03.530719
New Reviews found: {}
Updating at: 2019-04-28 19:04:02.721920
New Reviews found: {}
Updating at: 2019-04-28 19:06:02.907265
New Reviews found: {}
Updating at: 2019-04-28 19:08:03.155486
New Reviews found: {}
Updating at: 2019-04-28 19:10:03.486967
New Reviews found: {}
Updating at: 2019-04-28 19:12:02.732022
New Reviews found: {}
Updating at: 2019-04-28 19:14:03.038263
New Reviews found: {}
Updating at: 2019-04-28 19:16:03.392478
New Reviews found: {}
Updating at: 2019-04-28 19:18:03.574680
New Reviews found: {}
Updating at: 2019-04-28 19:20:02.859145
New Reviews found: {}
Updating at: 2019-04-28 19:22:03.057563
New Reviews found: {}
Updating at: 2019-04-28 19:24:03.295516
New Reviews found: {}
Updating at: 2019-04-28 19:26:03.508709
New Reviews found: {}
Updating at: 2019-04-28 19:28:02.816588
New Reviews found: {}
Updating at: 2019-04-28 19:30:03.127680
New Reviews found: {}
Updating at: 2019-04-28 19:32:03.407672
New Reviews found: {}
Updating at: 2019-04-28 19:34:03.702656
New Reviews found: {}
Updating at: 2019-04-28 19:36:02.993544
New Reviews found: {}
Updating at: 2019-04-28 19:38:03.179658
New Reviews found: {}
Updating at: 2019-04-28 19:40:03.475788
New Reviews found: {}
Updating at: 2019-04-28 19:42:03.690420
New Reviews found: {}
Updating at: 2019-04-28 19:44:02.907277
New Reviews found: {}
Updating at: 2019-04-28 19:46:03.206978
New Reviews found: {}
Updating at: 2019-04-28 19:48:03.449581
New Reviews found: {}
Updating at: 2019-04-28 19:50:03.644020
New Reviews found: {}
Updating at: 2019-04-28 19:52:02.865222
New Reviews found: {}
Updating at: 2019-04-28 19:54:03.112186
New Reviews found: {}
Updating at: 2019-04-28 19:56:03.303440
New Reviews found: {}
Updating at: 2019-04-28 19:58:03.488482
New Reviews found: {}
Updating at: 2019-04-28 20:00:12.585717
New Reviews found: {'1u6v3Jmyd7wqKHZzUFT60A': ['Yelp', 'CoreLife Eatery', '4/26/2019', 'The food I ordered from here was INEDBILE.I also ordered a "stake plate" and almost threw up at the gamey smell that hit my nose after opening the cover, also the "salad" was just a couple pieces of undressed lettuce. Highly recommend not getting food from here.', 1, 0, '594kvUIZoNGj3TuG1afb4w']}
Updating at: 2019-04-28 20:02:12.410370
New Reviews found: {}
Updating at: 2019-04-28 20:04:12.297821
New Reviews found: {}
Updating at: 2019-04-28 20:06:13.210134
New Reviews found: {}
Updating at: 2019-04-28 20:08:13.094904
New Reviews found: {}
Updating at: 2019-04-28 20:10:12.947794
New Reviews found: {}
Updating at: 2019-04-28 20:12:13.011707
New Reviews found: {}
Updating at: 2019-04-28 20:14:12.586837
New Reviews found: {}
Updating at: 2019-04-28 20:16:13.626834
New Reviews found: {}
Updating at: 2019-04-28 20:18:12.404851
New Reviews found: {}
Updating at: 2019-04-28 20:20:13.250686
New Reviews found: {}
Updating at: 2019-04-28 20:22:14.124943
New Reviews found: {}
Updating at: 2019-04-28 20:24:12.458405
New Reviews found: {}
Updating at: 2019-04-28 20:26:12.492260
New Reviews found: {}
Updating at: 2019-04-28 20:28:12.916105
New Reviews found: {}
Updating at: 2019-04-28 20:30:13.348649
New Reviews found: {}
Updating at: 2019-04-28 20:32:12.878525
New Reviews found: {}
Traceback (most recent call last):
  File "/home/hduser1/Restuarant_Review/dbms.py", line 33, in initialize_yelp
    return pd.read_hdf('yelp.hdf','yelp_df')
  File "/usr/local/lib/python3.6/dist-packages/pandas/io/pytables.py", line 366, in read_hdf
    'File {path} does not exist'.format(path=path_or_buf))
FileNotFoundError: File yelp.hdf does not exist

During handling of the above exception, another exception occurred:

Traceback (most recent call last):
  File "/home/hduser1/Restuarant_Review/UpdateYelp.py", line 4, in <module>
    df = dbms.initialize_yelp()
  File "/home/hduser1/Restuarant_Review/dbms.py", line 35, in initialize_yelp
    big_list = read_data('YelpData.txt')
  File "/home/hduser1/Restuarant_Review/dbms.py", line 21, in read_data
    with open(path,'rb') as f:
FileNotFoundError: [Errno 2] No such file or directory: 'YelpData.txt'
Traceback (most recent call last):
  File "/home/hduser1/Restuarant_Review/dbms.py", line 33, in initialize_yelp
    return pd.read_hdf('yelp.hdf','yelp_df')
  File "/usr/local/lib/python3.6/dist-packages/pandas/io/pytables.py", line 366, in read_hdf
    'File {path} does not exist'.format(path=path_or_buf))
FileNotFoundError: File yelp.hdf does not exist

During handling of the above exception, another exception occurred:

Traceback (most recent call last):
  File "/home/hduser1/Restuarant_Review/UpdateYelp.py", line 4, in <module>
    df = dbms.initialize_yelp()
  File "/home/hduser1/Restuarant_Review/dbms.py", line 35, in initialize_yelp
    big_list = read_data('YelpData.txt')
  File "/home/hduser1/Restuarant_Review/dbms.py", line 21, in read_data
    with open(path,'rb') as f:
FileNotFoundError: [Errno 2] No such file or directory: 'YelpData.txt'
Traceback (most recent call last):
  File "/home/hduser1/Restuarant_Review/dbms.py", line 33, in initialize_yelp
    return pd.read_hdf('yelp.hdf','yelp_df')
  File "/usr/local/lib/python3.6/dist-packages/pandas/io/pytables.py", line 366, in read_hdf
    'File {path} does not exist'.format(path=path_or_buf))
FileNotFoundError: File yelp.hdf does not exist

During handling of the above exception, another exception occurred:

Traceback (most recent call last):
  File "/home/hduser1/Restuarant_Review/UpdateYelp.py", line 4, in <module>
    df = dbms.initialize_yelp()
  File "/home/hduser1/Restuarant_Review/dbms.py", line 35, in initialize_yelp
    big_list = read_data('YelpData.txt')
  File "/home/hduser1/Restuarant_Review/dbms.py", line 21, in read_data
    with open(path,'rb') as f:
FileNotFoundError: [Errno 2] No such file or directory: 'YelpData.txt'
Traceback (most recent call last):
  File "/home/hduser1/Restuarant_Review/dbms.py", line 33, in initialize_yelp
    return pd.read_hdf('yelp.hdf','yelp_df')
  File "/usr/local/lib/python3.6/dist-packages/pandas/io/pytables.py", line 366, in read_hdf
    'File {path} does not exist'.format(path=path_or_buf))
FileNotFoundError: File yelp.hdf does not exist

During handling of the above exception, another exception occurred:

Traceback (most recent call last):
  File "/home/hduser1/Restuarant_Review/UpdateYelp.py", line 4, in <module>
    df = dbms.initialize_yelp()
  File "/home/hduser1/Restuarant_Review/dbms.py", line 35, in initialize_yelp
    big_list = read_data('YelpData.txt')
  File "/home/hduser1/Restuarant_Review/dbms.py", line 21, in read_data
    with open(path,'rb') as f:
FileNotFoundError: [Errno 2] No such file or directory: 'YelpData.txt'
Traceback (most recent call last):
  File "/home/hduser1/Restuarant_Review/dbms.py", line 33, in initialize_yelp
    return pd.read_hdf('yelp.hdf','yelp_df')
  File "/usr/local/lib/python3.6/dist-packages/pandas/io/pytables.py", line 366, in read_hdf
    'File {path} does not exist'.format(path=path_or_buf))
FileNotFoundError: File yelp.hdf does not exist

During handling of the above exception, another exception occurred:

Traceback (most recent call last):
  File "/home/hduser1/Restuarant_Review/UpdateYelp.py", line 4, in <module>
    df = dbms.initialize_yelp()
  File "/home/hduser1/Restuarant_Review/dbms.py", line 35, in initialize_yelp
    big_list = read_data('YelpData.txt')
  File "/home/hduser1/Restuarant_Review/dbms.py", line 21, in read_data
    with open(path,'rb') as f:
FileNotFoundError: [Errno 2] No such file or directory: 'YelpData.txt'
Traceback (most recent call last):
  File "/home/hduser1/Restuarant_Review/dbms.py", line 33, in initialize_yelp
    return pd.read_hdf('yelp.hdf','yelp_df')
  File "/usr/local/lib/python3.6/dist-packages/pandas/io/pytables.py", line 366, in read_hdf
    'File {path} does not exist'.format(path=path_or_buf))
FileNotFoundError: File yelp.hdf does not exist

During handling of the above exception, another exception occurred:

Traceback (most recent call last):
  File "/home/hduser1/Restuarant_Review/UpdateYelp.py", line 4, in <module>
    df = dbms.initialize_yelp()
  File "/home/hduser1/Restuarant_Review/dbms.py", line 35, in initialize_yelp
    big_list = read_data('YelpData.txt')
  File "/home/hduser1/Restuarant_Review/dbms.py", line 21, in read_data
    with open(path,'rb') as f:
FileNotFoundError: [Errno 2] No such file or directory: 'YelpData.txt'
Traceback (most recent call last):
  File "/home/hduser1/Restuarant_Review/dbms.py", line 33, in initialize_yelp
    return pd.read_hdf('yelp.hdf','yelp_df')
  File "/usr/local/lib/python3.6/dist-packages/pandas/io/pytables.py", line 366, in read_hdf
    'File {path} does not exist'.format(path=path_or_buf))
FileNotFoundError: File yelp.hdf does not exist

During handling of the above exception, another exception occurred:

Traceback (most recent call last):
  File "/home/hduser1/Restuarant_Review/UpdateYelp.py", line 4, in <module>
    df = dbms.initialize_yelp()
  File "/home/hduser1/Restuarant_Review/dbms.py", line 35, in initialize_yelp
    big_list = read_data('YelpData.txt')
  File "/home/hduser1/Restuarant_Review/dbms.py", line 21, in read_data
    with open(path,'rb') as f:
FileNotFoundError: [Errno 2] No such file or directory: 'YelpData.txt'
Traceback (most recent call last):
  File "/home/hduser1/Restuarant_Review/dbms.py", line 33, in initialize_yelp
    return pd.read_hdf('yelp.hdf','yelp_df')
  File "/usr/local/lib/python3.6/dist-packages/pandas/io/pytables.py", line 366, in read_hdf
    'File {path} does not exist'.format(path=path_or_buf))
FileNotFoundError: File yelp.hdf does not exist

During handling of the above exception, another exception occurred:

Traceback (most recent call last):
  File "/home/hduser1/Restuarant_Review/UpdateYelp.py", line 4, in <module>
    df = dbms.initialize_yelp()
  File "/home/hduser1/Restuarant_Review/dbms.py", line 35, in initialize_yelp
    big_list = read_data('YelpData.txt')
  File "/home/hduser1/Restuarant_Review/dbms.py", line 21, in read_data
    with open(path,'rb') as f:
FileNotFoundError: [Errno 2] No such file or directory: 'YelpData.txt'
Traceback (most recent call last):
  File "/home/hduser1/Restuarant_Review/dbms.py", line 33, in initialize_yelp
    return pd.read_hdf('yelp.hdf','yelp_df')
  File "/usr/local/lib/python3.6/dist-packages/pandas/io/pytables.py", line 366, in read_hdf
    'File {path} does not exist'.format(path=path_or_buf))
FileNotFoundError: File yelp.hdf does not exist

During handling of the above exception, another exception occurred:

Traceback (most recent call last):
  File "/home/hduser1/Restuarant_Review/UpdateYelp.py", line 4, in <module>
    df = dbms.initialize_yelp()
  File "/home/hduser1/Restuarant_Review/dbms.py", line 35, in initialize_yelp
    big_list = read_data('YelpData.txt')
  File "/home/hduser1/Restuarant_Review/dbms.py", line 21, in read_data
    with open(path,'rb') as f:
FileNotFoundError: [Errno 2] No such file or directory: 'YelpData.txt'
Traceback (most recent call last):
  File "/home/hduser1/Restuarant_Review/dbms.py", line 33, in initialize_yelp
    return pd.read_hdf('yelp.hdf','yelp_df')
  File "/usr/local/lib/python3.6/dist-packages/pandas/io/pytables.py", line 366, in read_hdf
    'File {path} does not exist'.format(path=path_or_buf))
FileNotFoundError: File yelp.hdf does not exist

During handling of the above exception, another exception occurred:

Traceback (most recent call last):
  File "/home/hduser1/Restuarant_Review/UpdateYelp.py", line 4, in <module>
    df = dbms.initialize_yelp()
  File "/home/hduser1/Restuarant_Review/dbms.py", line 35, in initialize_yelp
    big_list = read_data('YelpData.txt')
  File "/home/hduser1/Restuarant_Review/dbms.py", line 21, in read_data
    with open(path,'rb') as f:
FileNotFoundError: [Errno 2] No such file or directory: 'YelpData.txt'
Traceback (most recent call last):
  File "/home/hduser1/Restuarant_Review/dbms.py", line 33, in initialize_yelp
    return pd.read_hdf('yelp.hdf','yelp_df')
  File "/usr/local/lib/python3.6/dist-packages/pandas/io/pytables.py", line 366, in read_hdf
    'File {path} does not exist'.format(path=path_or_buf))
FileNotFoundError: File yelp.hdf does not exist

During handling of the above exception, another exception occurred:

Traceback (most recent call last):
  File "/home/hduser1/Restuarant_Review/UpdateYelp.py", line 4, in <module>
    df = dbms.initialize_yelp()
  File "/home/hduser1/Restuarant_Review/dbms.py", line 35, in initialize_yelp
    big_list = read_data('YelpData.txt')
  File "/home/hduser1/Restuarant_Review/dbms.py", line 21, in read_data
    with open(path,'rb') as f:
FileNotFoundError: [Errno 2] No such file or directory: 'YelpData.txt'
Traceback (most recent call last):
  File "/home/hduser1/Restuarant_Review/dbms.py", line 33, in initialize_yelp
    return pd.read_hdf('yelp.hdf','yelp_df')
  File "/usr/local/lib/python3.6/dist-packages/pandas/io/pytables.py", line 366, in read_hdf
    'File {path} does not exist'.format(path=path_or_buf))
FileNotFoundError: File yelp.hdf does not exist

During handling of the above exception, another exception occurred:

Traceback (most recent call last):
  File "/home/hduser1/Restuarant_Review/UpdateYelp.py", line 4, in <module>
    df = dbms.initialize_yelp()
  File "/home/hduser1/Restuarant_Review/dbms.py", line 35, in initialize_yelp
    big_list = read_data('YelpData.txt')
  File "/home/hduser1/Restuarant_Review/dbms.py", line 21, in read_data
    with open(path,'rb') as f:
FileNotFoundError: [Errno 2] No such file or directory: 'YelpData.txt'
Traceback (most recent call last):
  File "/home/hduser1/Restuarant_Review/dbms.py", line 33, in initialize_yelp
    return pd.read_hdf('yelp.hdf','yelp_df')
  File "/usr/local/lib/python3.6/dist-packages/pandas/io/pytables.py", line 366, in read_hdf
    'File {path} does not exist'.format(path=path_or_buf))
FileNotFoundError: File yelp.hdf does not exist

During handling of the above exception, another exception occurred:

Traceback (most recent call last):
  File "/home/hduser1/Restuarant_Review/UpdateYelp.py", line 4, in <module>
    df = dbms.initialize_yelp()
  File "/home/hduser1/Restuarant_Review/dbms.py", line 35, in initialize_yelp
    big_list = read_data('YelpData.txt')
  File "/home/hduser1/Restuarant_Review/dbms.py", line 21, in read_data
    with open(path,'rb') as f:
FileNotFoundError: [Errno 2] No such file or directory: 'YelpData.txt'
Traceback (most recent call last):
  File "/home/hduser1/Restuarant_Review/dbms.py", line 33, in initialize_yelp
    return pd.read_hdf('yelp.hdf','yelp_df')
  File "/usr/local/lib/python3.6/dist-packages/pandas/io/pytables.py", line 366, in read_hdf
    'File {path} does not exist'.format(path=path_or_buf))
FileNotFoundError: File yelp.hdf does not exist

During handling of the above exception, another exception occurred:

Traceback (most recent call last):
  File "/home/hduser1/Restuarant_Review/UpdateYelp.py", line 4, in <module>
    df = dbms.initialize_yelp()
  File "/home/hduser1/Restuarant_Review/dbms.py", line 35, in initialize_yelp
    big_list = read_data('YelpData.txt')
  File "/home/hduser1/Restuarant_Review/dbms.py", line 21, in read_data
    with open(path,'rb') as f:
FileNotFoundError: [Errno 2] No such file or directory: 'YelpData.txt'
Traceback (most recent call last):
  File "/home/hduser1/Restuarant_Review/dbms.py", line 33, in initialize_yelp
    return pd.read_hdf('yelp.hdf','yelp_df')
  File "/usr/local/lib/python3.6/dist-packages/pandas/io/pytables.py", line 366, in read_hdf
    'File {path} does not exist'.format(path=path_or_buf))
FileNotFoundError: File yelp.hdf does not exist

During handling of the above exception, another exception occurred:

Traceback (most recent call last):
  File "/home/hduser1/Restuarant_Review/UpdateYelp.py", line 4, in <module>
    df = dbms.initialize_yelp()
  File "/home/hduser1/Restuarant_Review/dbms.py", line 35, in initialize_yelp
    big_list = read_data('YelpData.txt')
  File "/home/hduser1/Restuarant_Review/dbms.py", line 21, in read_data
    with open(path,'rb') as f:
FileNotFoundError: [Errno 2] No such file or directory: 'YelpData.txt'
Traceback (most recent call last):
  File "/home/hduser1/Restuarant_Review/dbms.py", line 33, in initialize_yelp
    return pd.read_hdf('yelp.hdf','yelp_df')
  File "/usr/local/lib/python3.6/dist-packages/pandas/io/pytables.py", line 366, in read_hdf
    'File {path} does not exist'.format(path=path_or_buf))
FileNotFoundError: File yelp.hdf does not exist

During handling of the above exception, another exception occurred:

Traceback (most recent call last):
  File "/home/hduser1/Restuarant_Review/UpdateYelp.py", line 4, in <module>
    df = dbms.initialize_yelp()
  File "/home/hduser1/Restuarant_Review/dbms.py", line 35, in initialize_yelp
    big_list = read_data('YelpData.txt')
  File "/home/hduser1/Restuarant_Review/dbms.py", line 21, in read_data
    with open(path,'rb') as f:
FileNotFoundError: [Errno 2] No such file or directory: 'YelpData.txt'
Traceback (most recent call last):
  File "/home/hduser1/Restuarant_Review/dbms.py", line 33, in initialize_yelp
    return pd.read_hdf('yelp.hdf','yelp_df')
  File "/usr/local/lib/python3.6/dist-packages/pandas/io/pytables.py", line 366, in read_hdf
    'File {path} does not exist'.format(path=path_or_buf))
FileNotFoundError: File yelp.hdf does not exist

During handling of the above exception, another exception occurred:

Traceback (most recent call last):
  File "/home/hduser1/Restuarant_Review/UpdateYelp.py", line 4, in <module>
    df = dbms.initialize_yelp()
  File "/home/hduser1/Restuarant_Review/dbms.py", line 35, in initialize_yelp
    big_list = read_data('YelpData.txt')
  File "/home/hduser1/Restuarant_Review/dbms.py", line 21, in read_data
    with open(path,'rb') as f:
FileNotFoundError: [Errno 2] No such file or directory: 'YelpData.txt'
Traceback (most recent call last):
  File "/home/hduser1/Restuarant_Review/dbms.py", line 33, in initialize_yelp
    return pd.read_hdf('yelp.hdf','yelp_df')
  File "/usr/local/lib/python3.6/dist-packages/pandas/io/pytables.py", line 366, in read_hdf
    'File {path} does not exist'.format(path=path_or_buf))
FileNotFoundError: File yelp.hdf does not exist

During handling of the above exception, another exception occurred:

Traceback (most recent call last):
  File "/home/hduser1/Restuarant_Review/UpdateYelp.py", line 4, in <module>
    df = dbms.initialize_yelp()
  File "/home/hduser1/Restuarant_Review/dbms.py", line 35, in initialize_yelp
    big_list = read_data('YelpData.txt')
  File "/home/hduser1/Restuarant_Review/dbms.py", line 21, in read_data
    with open(path,'rb') as f:
FileNotFoundError: [Errno 2] No such file or directory: 'YelpData.txt'
Traceback (most recent call last):
  File "/home/hduser1/Restuarant_Review/dbms.py", line 33, in initialize_yelp
    return pd.read_hdf('yelp.hdf','yelp_df')
  File "/usr/local/lib/python3.6/dist-packages/pandas/io/pytables.py", line 366, in read_hdf
    'File {path} does not exist'.format(path=path_or_buf))
FileNotFoundError: File yelp.hdf does not exist

During handling of the above exception, another exception occurred:

Traceback (most recent call last):
  File "/home/hduser1/Restuarant_Review/UpdateYelp.py", line 4, in <module>
    df = dbms.initialize_yelp()
  File "/home/hduser1/Restuarant_Review/dbms.py", line 35, in initialize_yelp
    big_list = read_data('YelpData.txt')
  File "/home/hduser1/Restuarant_Review/dbms.py", line 21, in read_data
    with open(path,'rb') as f:
FileNotFoundError: [Errno 2] No such file or directory: 'YelpData.txt'
Traceback (most recent call last):
  File "/home/hduser1/Restuarant_Review/dbms.py", line 33, in initialize_yelp
    return pd.read_hdf('yelp.hdf','yelp_df')
  File "/usr/local/lib/python3.6/dist-packages/pandas/io/pytables.py", line 366, in read_hdf
    'File {path} does not exist'.format(path=path_or_buf))
FileNotFoundError: File yelp.hdf does not exist

During handling of the above exception, another exception occurred:

Traceback (most recent call last):
  File "/home/hduser1/Restuarant_Review/UpdateYelp.py", line 4, in <module>
    df = dbms.initialize_yelp()
  File "/home/hduser1/Restuarant_Review/dbms.py", line 35, in initialize_yelp
    big_list = read_data('YelpData.txt')
  File "/home/hduser1/Restuarant_Review/dbms.py", line 21, in read_data
    with open(path,'rb') as f:
FileNotFoundError: [Errno 2] No such file or directory: 'YelpData.txt'
Traceback (most recent call last):
  File "/home/hduser1/Restuarant_Review/dbms.py", line 33, in initialize_yelp
    return pd.read_hdf('yelp.hdf','yelp_df')
  File "/usr/local/lib/python3.6/dist-packages/pandas/io/pytables.py", line 366, in read_hdf
    'File {path} does not exist'.format(path=path_or_buf))
FileNotFoundError: File yelp.hdf does not exist

During handling of the above exception, another exception occurred:

Traceback (most recent call last):
  File "/home/hduser1/Restuarant_Review/UpdateYelp.py", line 4, in <module>
    df = dbms.initialize_yelp()
  File "/home/hduser1/Restuarant_Review/dbms.py", line 35, in initialize_yelp
    big_list = read_data('YelpData.txt')
  File "/home/hduser1/Restuarant_Review/dbms.py", line 21, in read_data
    with open(path,'rb') as f:
FileNotFoundError: [Errno 2] No such file or directory: 'YelpData.txt'
Traceback (most recent call last):
  File "/home/hduser1/Restuarant_Review/dbms.py", line 33, in initialize_yelp
    return pd.read_hdf('yelp.hdf','yelp_df')
  File "/usr/local/lib/python3.6/dist-packages/pandas/io/pytables.py", line 366, in read_hdf
    'File {path} does not exist'.format(path=path_or_buf))
FileNotFoundError: File yelp.hdf does not exist

During handling of the above exception, another exception occurred:

Traceback (most recent call last):
  File "/home/hduser1/Restuarant_Review/UpdateYelp.py", line 4, in <module>
    df = dbms.initialize_yelp()
  File "/home/hduser1/Restuarant_Review/dbms.py", line 35, in initialize_yelp
    big_list = read_data('YelpData.txt')
  File "/home/hduser1/Restuarant_Review/dbms.py", line 21, in read_data
    with open(path,'rb') as f:
FileNotFoundError: [Errno 2] No such file or directory: 'YelpData.txt'
Traceback (most recent call last):
  File "/home/hduser1/Restuarant_Review/dbms.py", line 33, in initialize_yelp
    return pd.read_hdf('yelp.hdf','yelp_df')
  File "/usr/local/lib/python3.6/dist-packages/pandas/io/pytables.py", line 366, in read_hdf
    'File {path} does not exist'.format(path=path_or_buf))
FileNotFoundError: File yelp.hdf does not exist

During handling of the above exception, another exception occurred:

Traceback (most recent call last):
  File "/home/hduser1/Restuarant_Review/UpdateYelp.py", line 4, in <module>
    df = dbms.initialize_yelp()
  File "/home/hduser1/Restuarant_Review/dbms.py", line 35, in initialize_yelp
    big_list = read_data('YelpData.txt')
  File "/home/hduser1/Restuarant_Review/dbms.py", line 21, in read_data
    with open(path,'rb') as f:
FileNotFoundError: [Errno 2] No such file or directory: 'YelpData.txt'
Traceback (most recent call last):
  File "/home/hduser1/Restuarant_Review/dbms.py", line 33, in initialize_yelp
    return pd.read_hdf('yelp.hdf','yelp_df')
  File "/usr/local/lib/python3.6/dist-packages/pandas/io/pytables.py", line 366, in read_hdf
    'File {path} does not exist'.format(path=path_or_buf))
FileNotFoundError: File yelp.hdf does not exist

During handling of the above exception, another exception occurred:

Traceback (most recent call last):
  File "/home/hduser1/Restuarant_Review/UpdateYelp.py", line 4, in <module>
    df = dbms.initialize_yelp()
  File "/home/hduser1/Restuarant_Review/dbms.py", line 35, in initialize_yelp
    big_list = read_data('YelpData.txt')
  File "/home/hduser1/Restuarant_Review/dbms.py", line 21, in read_data
    with open(path,'rb') as f:
FileNotFoundError: [Errno 2] No such file or directory: 'YelpData.txt'
Traceback (most recent call last):
  File "/home/hduser1/Restuarant_Review/dbms.py", line 33, in initialize_yelp
    return pd.read_hdf('yelp.hdf','yelp_df')
  File "/usr/local/lib/python3.6/dist-packages/pandas/io/pytables.py", line 366, in read_hdf
    'File {path} does not exist'.format(path=path_or_buf))
FileNotFoundError: File yelp.hdf does not exist

During handling of the above exception, another exception occurred:

Traceback (most recent call last):
  File "/home/hduser1/Restuarant_Review/UpdateYelp.py", line 4, in <module>
    df = dbms.initialize_yelp()
  File "/home/hduser1/Restuarant_Review/dbms.py", line 35, in initialize_yelp
    big_list = read_data('YelpData.txt')
  File "/home/hduser1/Restuarant_Review/dbms.py", line 21, in read_data
    with open(path,'rb') as f:
FileNotFoundError: [Errno 2] No such file or directory: 'YelpData.txt'
Traceback (most recent call last):
  File "/home/hduser1/Restuarant_Review/dbms.py", line 33, in initialize_yelp
    return pd.read_hdf('yelp.hdf','yelp_df')
  File "/usr/local/lib/python3.6/dist-packages/pandas/io/pytables.py", line 366, in read_hdf
    'File {path} does not exist'.format(path=path_or_buf))
FileNotFoundError: File yelp.hdf does not exist

During handling of the above exception, another exception occurred:

Traceback (most recent call last):
  File "/home/hduser1/Restuarant_Review/UpdateYelp.py", line 4, in <module>
    df = dbms.initialize_yelp()
  File "/home/hduser1/Restuarant_Review/dbms.py", line 35, in initialize_yelp
    big_list = read_data('YelpData.txt')
  File "/home/hduser1/Restuarant_Review/dbms.py", line 21, in read_data
    with open(path,'rb') as f:
FileNotFoundError: [Errno 2] No such file or directory: 'YelpData.txt'
Traceback (most recent call last):
  File "/home/hduser1/Restuarant_Review/dbms.py", line 33, in initialize_yelp
    return pd.read_hdf('yelp.hdf','yelp_df')
  File "/usr/local/lib/python3.6/dist-packages/pandas/io/pytables.py", line 366, in read_hdf
    'File {path} does not exist'.format(path=path_or_buf))
FileNotFoundError: File yelp.hdf does not exist

During handling of the above exception, another exception occurred:

Traceback (most recent call last):
  File "/home/hduser1/Restuarant_Review/UpdateYelp.py", line 4, in <module>
    df = dbms.initialize_yelp()
  File "/home/hduser1/Restuarant_Review/dbms.py", line 35, in initialize_yelp
    big_list = read_data('YelpData.txt')
  File "/home/hduser1/Restuarant_Review/dbms.py", line 21, in read_data
    with open(path,'rb') as f:
FileNotFoundError: [Errno 2] No such file or directory: 'YelpData.txt'
Traceback (most recent call last):
  File "/home/hduser1/Restuarant_Review/dbms.py", line 33, in initialize_yelp
    return pd.read_hdf('yelp.hdf','yelp_df')
  File "/usr/local/lib/python3.6/dist-packages/pandas/io/pytables.py", line 366, in read_hdf
    'File {path} does not exist'.format(path=path_or_buf))
FileNotFoundError: File yelp.hdf does not exist

During handling of the above exception, another exception occurred:

Traceback (most recent call last):
  File "/home/hduser1/Restuarant_Review/UpdateYelp.py", line 4, in <module>
    df = dbms.initialize_yelp()
  File "/home/hduser1/Restuarant_Review/dbms.py", line 35, in initialize_yelp
    big_list = read_data('YelpData.txt')
  File "/home/hduser1/Restuarant_Review/dbms.py", line 21, in read_data
    with open(path,'rb') as f:
FileNotFoundError: [Errno 2] No such file or directory: 'YelpData.txt'
Traceback (most recent call last):
  File "/home/hduser1/Restuarant_Review/dbms.py", line 33, in initialize_yelp
    return pd.read_hdf('yelp.hdf','yelp_df')
  File "/usr/local/lib/python3.6/dist-packages/pandas/io/pytables.py", line 366, in read_hdf
    'File {path} does not exist'.format(path=path_or_buf))
FileNotFoundError: File yelp.hdf does not exist

During handling of the above exception, another exception occurred:

Traceback (most recent call last):
  File "/home/hduser1/Restuarant_Review/UpdateYelp.py", line 4, in <module>
    df = dbms.initialize_yelp()
  File "/home/hduser1/Restuarant_Review/dbms.py", line 35, in initialize_yelp
    big_list = read_data('YelpData.txt')
  File "/home/hduser1/Restuarant_Review/dbms.py", line 21, in read_data
    with open(path,'rb') as f:
FileNotFoundError: [Errno 2] No such file or directory: 'YelpData.txt'
Traceback (most recent call last):
  File "/home/hduser1/Restuarant_Review/dbms.py", line 33, in initialize_yelp
    return pd.read_hdf('yelp.hdf','yelp_df')
  File "/usr/local/lib/python3.6/dist-packages/pandas/io/pytables.py", line 366, in read_hdf
    'File {path} does not exist'.format(path=path_or_buf))
FileNotFoundError: File yelp.hdf does not exist

During handling of the above exception, another exception occurred:

Traceback (most recent call last):
  File "/home/hduser1/Restuarant_Review/UpdateYelp.py", line 4, in <module>
    df = dbms.initialize_yelp()
  File "/home/hduser1/Restuarant_Review/dbms.py", line 35, in initialize_yelp
    big_list = read_data('YelpData.txt')
  File "/home/hduser1/Restuarant_Review/dbms.py", line 21, in read_data
    with open(path,'rb') as f:
FileNotFoundError: [Errno 2] No such file or directory: 'YelpData.txt'
Traceback (most recent call last):
  File "/home/hduser1/Restuarant_Review/dbms.py", line 33, in initialize_yelp
    return pd.read_hdf('yelp.hdf','yelp_df')
  File "/usr/local/lib/python3.6/dist-packages/pandas/io/pytables.py", line 366, in read_hdf
    'File {path} does not exist'.format(path=path_or_buf))
FileNotFoundError: File yelp.hdf does not exist

During handling of the above exception, another exception occurred:

Traceback (most recent call last):
  File "/home/hduser1/Restuarant_Review/UpdateYelp.py", line 4, in <module>
    df = dbms.initialize_yelp()
  File "/home/hduser1/Restuarant_Review/dbms.py", line 35, in initialize_yelp
    big_list = read_data('YelpData.txt')
  File "/home/hduser1/Restuarant_Review/dbms.py", line 21, in read_data
    with open(path,'rb') as f:
FileNotFoundError: [Errno 2] No such file or directory: 'YelpData.txt'
Traceback (most recent call last):
  File "/home/hduser1/Restuarant_Review/dbms.py", line 33, in initialize_yelp
    return pd.read_hdf('yelp.hdf','yelp_df')
  File "/usr/local/lib/python3.6/dist-packages/pandas/io/pytables.py", line 366, in read_hdf
    'File {path} does not exist'.format(path=path_or_buf))
FileNotFoundError: File yelp.hdf does not exist

During handling of the above exception, another exception occurred:

Traceback (most recent call last):
  File "/home/hduser1/Restuarant_Review/UpdateYelp.py", line 4, in <module>
    df = dbms.initialize_yelp()
  File "/home/hduser1/Restuarant_Review/dbms.py", line 35, in initialize_yelp
    big_list = read_data('YelpData.txt')
  File "/home/hduser1/Restuarant_Review/dbms.py", line 21, in read_data
    with open(path,'rb') as f:
FileNotFoundError: [Errno 2] No such file or directory: 'YelpData.txt'
Traceback (most recent call last):
  File "/home/hduser1/Restuarant_Review/dbms.py", line 33, in initialize_yelp
    return pd.read_hdf('yelp.hdf','yelp_df')
  File "/usr/local/lib/python3.6/dist-packages/pandas/io/pytables.py", line 366, in read_hdf
    'File {path} does not exist'.format(path=path_or_buf))
FileNotFoundError: File yelp.hdf does not exist

During handling of the above exception, another exception occurred:

Traceback (most recent call last):
  File "/home/hduser1/Restuarant_Review/UpdateYelp.py", line 4, in <module>
    df = dbms.initialize_yelp()
  File "/home/hduser1/Restuarant_Review/dbms.py", line 35, in initialize_yelp
    big_list = read_data('YelpData.txt')
  File "/home/hduser1/Restuarant_Review/dbms.py", line 21, in read_data
    with open(path,'rb') as f:
FileNotFoundError: [Errno 2] No such file or directory: 'YelpData.txt'
Traceback (most recent call last):
  File "/home/hduser1/Restuarant_Review/dbms.py", line 33, in initialize_yelp
    return pd.read_hdf('yelp.hdf','yelp_df')
  File "/usr/local/lib/python3.6/dist-packages/pandas/io/pytables.py", line 366, in read_hdf
    'File {path} does not exist'.format(path=path_or_buf))
FileNotFoundError: File yelp.hdf does not exist

During handling of the above exception, another exception occurred:

Traceback (most recent call last):
  File "/home/hduser1/Restuarant_Review/UpdateYelp.py", line 4, in <module>
    df = dbms.initialize_yelp()
  File "/home/hduser1/Restuarant_Review/dbms.py", line 35, in initialize_yelp
    big_list = read_data('YelpData.txt')
  File "/home/hduser1/Restuarant_Review/dbms.py", line 21, in read_data
    with open(path,'rb') as f:
FileNotFoundError: [Errno 2] No such file or directory: 'YelpData.txt'
Traceback (most recent call last):
  File "/home/hduser1/Restuarant_Review/dbms.py", line 33, in initialize_yelp
    return pd.read_hdf('yelp.hdf','yelp_df')
  File "/usr/local/lib/python3.6/dist-packages/pandas/io/pytables.py", line 366, in read_hdf
    'File {path} does not exist'.format(path=path_or_buf))
FileNotFoundError: File yelp.hdf does not exist

During handling of the above exception, another exception occurred:

Traceback (most recent call last):
  File "/home/hduser1/Restuarant_Review/UpdateYelp.py", line 4, in <module>
    df = dbms.initialize_yelp()
  File "/home/hduser1/Restuarant_Review/dbms.py", line 35, in initialize_yelp
    big_list = read_data('YelpData.txt')
  File "/home/hduser1/Restuarant_Review/dbms.py", line 21, in read_data
    with open(path,'rb') as f:
FileNotFoundError: [Errno 2] No such file or directory: 'YelpData.txt'
Traceback (most recent call last):
  File "/home/hduser1/Restuarant_Review/dbms.py", line 33, in initialize_yelp
    return pd.read_hdf('yelp.hdf','yelp_df')
  File "/usr/local/lib/python3.6/dist-packages/pandas/io/pytables.py", line 366, in read_hdf
    'File {path} does not exist'.format(path=path_or_buf))
FileNotFoundError: File yelp.hdf does not exist

During handling of the above exception, another exception occurred:

Traceback (most recent call last):
  File "/home/hduser1/Restuarant_Review/UpdateYelp.py", line 4, in <module>
    df = dbms.initialize_yelp()
  File "/home/hduser1/Restuarant_Review/dbms.py", line 35, in initialize_yelp
    big_list = read_data('YelpData.txt')
  File "/home/hduser1/Restuarant_Review/dbms.py", line 21, in read_data
    with open(path,'rb') as f:
FileNotFoundError: [Errno 2] No such file or directory: 'YelpData.txt'
Traceback (most recent call last):
  File "/home/hduser1/Restuarant_Review/dbms.py", line 33, in initialize_yelp
    return pd.read_hdf('yelp.hdf','yelp_df')
  File "/usr/local/lib/python3.6/dist-packages/pandas/io/pytables.py", line 366, in read_hdf
    'File {path} does not exist'.format(path=path_or_buf))
FileNotFoundError: File yelp.hdf does not exist

During handling of the above exception, another exception occurred:

Traceback (most recent call last):
  File "/home/hduser1/Restuarant_Review/UpdateYelp.py", line 4, in <module>
    df = dbms.initialize_yelp()
  File "/home/hduser1/Restuarant_Review/dbms.py", line 35, in initialize_yelp
    big_list = read_data('YelpData.txt')
  File "/home/hduser1/Restuarant_Review/dbms.py", line 21, in read_data
    with open(path,'rb') as f:
FileNotFoundError: [Errno 2] No such file or directory: 'YelpData.txt'
Traceback (most recent call last):
  File "/home/hduser1/Restuarant_Review/dbms.py", line 33, in initialize_yelp
    return pd.read_hdf('yelp.hdf','yelp_df')
  File "/usr/local/lib/python3.6/dist-packages/pandas/io/pytables.py", line 366, in read_hdf
    'File {path} does not exist'.format(path=path_or_buf))
FileNotFoundError: File yelp.hdf does not exist

During handling of the above exception, another exception occurred:

Traceback (most recent call last):
  File "/home/hduser1/Restuarant_Review/UpdateYelp.py", line 4, in <module>
    df = dbms.initialize_yelp()
  File "/home/hduser1/Restuarant_Review/dbms.py", line 35, in initialize_yelp
    big_list = read_data('YelpData.txt')
  File "/home/hduser1/Restuarant_Review/dbms.py", line 21, in read_data
    with open(path,'rb') as f:
FileNotFoundError: [Errno 2] No such file or directory: 'YelpData.txt'
Traceback (most recent call last):
  File "/home/hduser1/Restuarant_Review/dbms.py", line 33, in initialize_yelp
    return pd.read_hdf('yelp.hdf','yelp_df')
  File "/usr/local/lib/python3.6/dist-packages/pandas/io/pytables.py", line 366, in read_hdf
    'File {path} does not exist'.format(path=path_or_buf))
FileNotFoundError: File yelp.hdf does not exist

During handling of the above exception, another exception occurred:

Traceback (most recent call last):
  File "/home/hduser1/Restuarant_Review/UpdateYelp.py", line 4, in <module>
    df = dbms.initialize_yelp()
  File "/home/hduser1/Restuarant_Review/dbms.py", line 35, in initialize_yelp
    big_list = read_data('YelpData.txt')
  File "/home/hduser1/Restuarant_Review/dbms.py", line 21, in read_data
    with open(path,'rb') as f:
FileNotFoundError: [Errno 2] No such file or directory: 'YelpData.txt'
Traceback (most recent call last):
  File "/home/hduser1/Restuarant_Review/dbms.py", line 33, in initialize_yelp
    return pd.read_hdf('yelp.hdf','yelp_df')
  File "/usr/local/lib/python3.6/dist-packages/pandas/io/pytables.py", line 366, in read_hdf
    'File {path} does not exist'.format(path=path_or_buf))
FileNotFoundError: File yelp.hdf does not exist

During handling of the above exception, another exception occurred:

Traceback (most recent call last):
  File "/home/hduser1/Restuarant_Review/UpdateYelp.py", line 4, in <module>
    df = dbms.initialize_yelp()
  File "/home/hduser1/Restuarant_Review/dbms.py", line 35, in initialize_yelp
    big_list = read_data('YelpData.txt')
  File "/home/hduser1/Restuarant_Review/dbms.py", line 21, in read_data
    with open(path,'rb') as f:
FileNotFoundError: [Errno 2] No such file or directory: 'YelpData.txt'
Traceback (most recent call last):
  File "/home/hduser1/Restuarant_Review/dbms.py", line 33, in initialize_yelp
    return pd.read_hdf('yelp.hdf','yelp_df')
  File "/usr/local/lib/python3.6/dist-packages/pandas/io/pytables.py", line 366, in read_hdf
    'File {path} does not exist'.format(path=path_or_buf))
FileNotFoundError: File yelp.hdf does not exist

During handling of the above exception, another exception occurred:

Traceback (most recent call last):
  File "/home/hduser1/Restuarant_Review/UpdateYelp.py", line 4, in <module>
    df = dbms.initialize_yelp()
  File "/home/hduser1/Restuarant_Review/dbms.py", line 35, in initialize_yelp
    big_list = read_data('YelpData.txt')
  File "/home/hduser1/Restuarant_Review/dbms.py", line 21, in read_data
    with open(path,'rb') as f:
FileNotFoundError: [Errno 2] No such file or directory: 'YelpData.txt'
Traceback (most recent call last):
  File "/home/hduser1/Restuarant_Review/dbms.py", line 33, in initialize_yelp
    return pd.read_hdf('yelp.hdf','yelp_df')
  File "/usr/local/lib/python3.6/dist-packages/pandas/io/pytables.py", line 366, in read_hdf
    'File {path} does not exist'.format(path=path_or_buf))
FileNotFoundError: File yelp.hdf does not exist

During handling of the above exception, another exception occurred:

Traceback (most recent call last):
  File "/home/hduser1/Restuarant_Review/UpdateYelp.py", line 4, in <module>
    df = dbms.initialize_yelp()
  File "/home/hduser1/Restuarant_Review/dbms.py", line 35, in initialize_yelp
    big_list = read_data('YelpData.txt')
  File "/home/hduser1/Restuarant_Review/dbms.py", line 21, in read_data
    with open(path,'rb') as f:
FileNotFoundError: [Errno 2] No such file or directory: 'YelpData.txt'
Traceback (most recent call last):
  File "/home/hduser1/Restuarant_Review/dbms.py", line 33, in initialize_yelp
    return pd.read_hdf('yelp.hdf','yelp_df')
  File "/usr/local/lib/python3.6/dist-packages/pandas/io/pytables.py", line 366, in read_hdf
    'File {path} does not exist'.format(path=path_or_buf))
FileNotFoundError: File yelp.hdf does not exist

During handling of the above exception, another exception occurred:

Traceback (most recent call last):
  File "/home/hduser1/Restuarant_Review/UpdateYelp.py", line 4, in <module>
    df = dbms.initialize_yelp()
  File "/home/hduser1/Restuarant_Review/dbms.py", line 35, in initialize_yelp
    big_list = read_data('YelpData.txt')
  File "/home/hduser1/Restuarant_Review/dbms.py", line 21, in read_data
    with open(path,'rb') as f:
FileNotFoundError: [Errno 2] No such file or directory: 'YelpData.txt'
Traceback (most recent call last):
  File "/home/hduser1/Restuarant_Review/dbms.py", line 33, in initialize_yelp
    return pd.read_hdf('yelp.hdf','yelp_df')
  File "/usr/local/lib/python3.6/dist-packages/pandas/io/pytables.py", line 366, in read_hdf
    'File {path} does not exist'.format(path=path_or_buf))
FileNotFoundError: File yelp.hdf does not exist

During handling of the above exception, another exception occurred:

Traceback (most recent call last):
  File "/home/hduser1/Restuarant_Review/UpdateYelp.py", line 4, in <module>
    df = dbms.initialize_yelp()
  File "/home/hduser1/Restuarant_Review/dbms.py", line 35, in initialize_yelp
    big_list = read_data('YelpData.txt')
  File "/home/hduser1/Restuarant_Review/dbms.py", line 21, in read_data
    with open(path,'rb') as f:
FileNotFoundError: [Errno 2] No such file or directory: 'YelpData.txt'
Traceback (most recent call last):
  File "/home/hduser1/Restuarant_Review/dbms.py", line 33, in initialize_yelp
    return pd.read_hdf('yelp.hdf','yelp_df')
  File "/usr/local/lib/python3.6/dist-packages/pandas/io/pytables.py", line 366, in read_hdf
    'File {path} does not exist'.format(path=path_or_buf))
FileNotFoundError: File yelp.hdf does not exist

During handling of the above exception, another exception occurred:

Traceback (most recent call last):
  File "/home/hduser1/Restuarant_Review/UpdateYelp.py", line 4, in <module>
    df = dbms.initialize_yelp()
  File "/home/hduser1/Restuarant_Review/dbms.py", line 35, in initialize_yelp
    big_list = read_data('YelpData.txt')
  File "/home/hduser1/Restuarant_Review/dbms.py", line 21, in read_data
    with open(path,'rb') as f:
FileNotFoundError: [Errno 2] No such file or directory: 'YelpData.txt'
Traceback (most recent call last):
  File "/home/hduser1/Restuarant_Review/dbms.py", line 33, in initialize_yelp
    return pd.read_hdf('yelp.hdf','yelp_df')
  File "/usr/local/lib/python3.6/dist-packages/pandas/io/pytables.py", line 366, in read_hdf
    'File {path} does not exist'.format(path=path_or_buf))
FileNotFoundError: File yelp.hdf does not exist

During handling of the above exception, another exception occurred:

Traceback (most recent call last):
  File "/home/hduser1/Restuarant_Review/UpdateYelp.py", line 4, in <module>
    df = dbms.initialize_yelp()
  File "/home/hduser1/Restuarant_Review/dbms.py", line 35, in initialize_yelp
    big_list = read_data('YelpData.txt')
  File "/home/hduser1/Restuarant_Review/dbms.py", line 21, in read_data
    with open(path,'rb') as f:
FileNotFoundError: [Errno 2] No such file or directory: 'YelpData.txt'
Traceback (most recent call last):
  File "/home/hduser1/Restuarant_Review/dbms.py", line 33, in initialize_yelp
    return pd.read_hdf('yelp.hdf','yelp_df')
  File "/usr/local/lib/python3.6/dist-packages/pandas/io/pytables.py", line 366, in read_hdf
    'File {path} does not exist'.format(path=path_or_buf))
FileNotFoundError: File yelp.hdf does not exist

During handling of the above exception, another exception occurred:

Traceback (most recent call last):
  File "/home/hduser1/Restuarant_Review/UpdateYelp.py", line 4, in <module>
    df = dbms.initialize_yelp()
  File "/home/hduser1/Restuarant_Review/dbms.py", line 35, in initialize_yelp
    big_list = read_data('YelpData.txt')
  File "/home/hduser1/Restuarant_Review/dbms.py", line 21, in read_data
    with open(path,'rb') as f:
FileNotFoundError: [Errno 2] No such file or directory: 'YelpData.txt'
Traceback (most recent call last):
  File "/home/hduser1/Restuarant_Review/dbms.py", line 33, in initialize_yelp
    return pd.read_hdf('yelp.hdf','yelp_df')
  File "/usr/local/lib/python3.6/dist-packages/pandas/io/pytables.py", line 366, in read_hdf
    'File {path} does not exist'.format(path=path_or_buf))
FileNotFoundError: File yelp.hdf does not exist

During handling of the above exception, another exception occurred:

Traceback (most recent call last):
  File "/home/hduser1/Restuarant_Review/UpdateYelp.py", line 4, in <module>
    df = dbms.initialize_yelp()
  File "/home/hduser1/Restuarant_Review/dbms.py", line 35, in initialize_yelp
    big_list = read_data('YelpData.txt')
  File "/home/hduser1/Restuarant_Review/dbms.py", line 21, in read_data
    with open(path,'rb') as f:
FileNotFoundError: [Errno 2] No such file or directory: 'YelpData.txt'
Traceback (most recent call last):
  File "/home/hduser1/Restuarant_Review/dbms.py", line 33, in initialize_yelp
    return pd.read_hdf('yelp.hdf','yelp_df')
  File "/usr/local/lib/python3.6/dist-packages/pandas/io/pytables.py", line 366, in read_hdf
    'File {path} does not exist'.format(path=path_or_buf))
FileNotFoundError: File yelp.hdf does not exist

During handling of the above exception, another exception occurred:

Traceback (most recent call last):
  File "/home/hduser1/Restuarant_Review/UpdateYelp.py", line 4, in <module>
    df = dbms.initialize_yelp()
  File "/home/hduser1/Restuarant_Review/dbms.py", line 35, in initialize_yelp
    big_list = read_data('YelpData.txt')
  File "/home/hduser1/Restuarant_Review/dbms.py", line 21, in read_data
    with open(path,'rb') as f:
FileNotFoundError: [Errno 2] No such file or directory: 'YelpData.txt'
Traceback (most recent call last):
  File "/home/hduser1/Restuarant_Review/dbms.py", line 33, in initialize_yelp
    return pd.read_hdf('yelp.hdf','yelp_df')
  File "/usr/local/lib/python3.6/dist-packages/pandas/io/pytables.py", line 366, in read_hdf
    'File {path} does not exist'.format(path=path_or_buf))
FileNotFoundError: File yelp.hdf does not exist

During handling of the above exception, another exception occurred:

Traceback (most recent call last):
  File "/home/hduser1/Restuarant_Review/UpdateYelp.py", line 4, in <module>
    df = dbms.initialize_yelp()
  File "/home/hduser1/Restuarant_Review/dbms.py", line 35, in initialize_yelp
    big_list = read_data('YelpData.txt')
  File "/home/hduser1/Restuarant_Review/dbms.py", line 21, in read_data
    with open(path,'rb') as f:
FileNotFoundError: [Errno 2] No such file or directory: 'YelpData.txt'
Traceback (most recent call last):
  File "/home/hduser1/Restuarant_Review/dbms.py", line 33, in initialize_yelp
    return pd.read_hdf('yelp.hdf','yelp_df')
  File "/usr/local/lib/python3.6/dist-packages/pandas/io/pytables.py", line 366, in read_hdf
    'File {path} does not exist'.format(path=path_or_buf))
FileNotFoundError: File yelp.hdf does not exist

During handling of the above exception, another exception occurred:

Traceback (most recent call last):
  File "/home/hduser1/Restuarant_Review/UpdateYelp.py", line 4, in <module>
    df = dbms.initialize_yelp()
  File "/home/hduser1/Restuarant_Review/dbms.py", line 35, in initialize_yelp
    big_list = read_data('YelpData.txt')
  File "/home/hduser1/Restuarant_Review/dbms.py", line 21, in read_data
    with open(path,'rb') as f:
FileNotFoundError: [Errno 2] No such file or directory: 'YelpData.txt'
Traceback (most recent call last):
  File "/home/hduser1/Restuarant_Review/dbms.py", line 33, in initialize_yelp
    return pd.read_hdf('yelp.hdf','yelp_df')
  File "/usr/local/lib/python3.6/dist-packages/pandas/io/pytables.py", line 366, in read_hdf
    'File {path} does not exist'.format(path=path_or_buf))
FileNotFoundError: File yelp.hdf does not exist

During handling of the above exception, another exception occurred:

Traceback (most recent call last):
  File "/home/hduser1/Restuarant_Review/UpdateYelp.py", line 4, in <module>
    df = dbms.initialize_yelp()
  File "/home/hduser1/Restuarant_Review/dbms.py", line 35, in initialize_yelp
    big_list = read_data('YelpData.txt')
  File "/home/hduser1/Restuarant_Review/dbms.py", line 21, in read_data
    with open(path,'rb') as f:
FileNotFoundError: [Errno 2] No such file or directory: 'YelpData.txt'
Traceback (most recent call last):
  File "/home/hduser1/Restuarant_Review/dbms.py", line 33, in initialize_yelp
    return pd.read_hdf('yelp.hdf','yelp_df')
  File "/usr/local/lib/python3.6/dist-packages/pandas/io/pytables.py", line 366, in read_hdf
    'File {path} does not exist'.format(path=path_or_buf))
FileNotFoundError: File yelp.hdf does not exist

During handling of the above exception, another exception occurred:

Traceback (most recent call last):
  File "/home/hduser1/Restuarant_Review/UpdateYelp.py", line 4, in <module>
    df = dbms.initialize_yelp()
  File "/home/hduser1/Restuarant_Review/dbms.py", line 35, in initialize_yelp
    big_list = read_data('YelpData.txt')
  File "/home/hduser1/Restuarant_Review/dbms.py", line 21, in read_data
    with open(path,'rb') as f:
FileNotFoundError: [Errno 2] No such file or directory: 'YelpData.txt'
Traceback (most recent call last):
  File "/home/hduser1/Restuarant_Review/dbms.py", line 33, in initialize_yelp
    return pd.read_hdf('yelp.hdf','yelp_df')
  File "/usr/local/lib/python3.6/dist-packages/pandas/io/pytables.py", line 366, in read_hdf
    'File {path} does not exist'.format(path=path_or_buf))
FileNotFoundError: File yelp.hdf does not exist

During handling of the above exception, another exception occurred:

Traceback (most recent call last):
  File "/home/hduser1/Restuarant_Review/UpdateYelp.py", line 4, in <module>
    df = dbms.initialize_yelp()
  File "/home/hduser1/Restuarant_Review/dbms.py", line 35, in initialize_yelp
    big_list = read_data('YelpData.txt')
  File "/home/hduser1/Restuarant_Review/dbms.py", line 21, in read_data
    with open(path,'rb') as f:
FileNotFoundError: [Errno 2] No such file or directory: 'YelpData.txt'
Traceback (most recent call last):
  File "/home/hduser1/Restuarant_Review/dbms.py", line 33, in initialize_yelp
    return pd.read_hdf('yelp.hdf','yelp_df')
  File "/usr/local/lib/python3.6/dist-packages/pandas/io/pytables.py", line 366, in read_hdf
    'File {path} does not exist'.format(path=path_or_buf))
FileNotFoundError: File yelp.hdf does not exist

During handling of the above exception, another exception occurred:

Traceback (most recent call last):
  File "/home/hduser1/Restuarant_Review/UpdateYelp.py", line 4, in <module>
    df = dbms.initialize_yelp()
  File "/home/hduser1/Restuarant_Review/dbms.py", line 35, in initialize_yelp
    big_list = read_data('YelpData.txt')
  File "/home/hduser1/Restuarant_Review/dbms.py", line 21, in read_data
    with open(path,'rb') as f:
FileNotFoundError: [Errno 2] No such file or directory: 'YelpData.txt'
Traceback (most recent call last):
  File "/home/hduser1/Restuarant_Review/dbms.py", line 33, in initialize_yelp
    return pd.read_hdf('yelp.hdf','yelp_df')
  File "/usr/local/lib/python3.6/dist-packages/pandas/io/pytables.py", line 366, in read_hdf
    'File {path} does not exist'.format(path=path_or_buf))
FileNotFoundError: File yelp.hdf does not exist

During handling of the above exception, another exception occurred:

Traceback (most recent call last):
  File "/home/hduser1/Restuarant_Review/UpdateYelp.py", line 4, in <module>
    df = dbms.initialize_yelp()
  File "/home/hduser1/Restuarant_Review/dbms.py", line 35, in initialize_yelp
    big_list = read_data('YelpData.txt')
  File "/home/hduser1/Restuarant_Review/dbms.py", line 21, in read_data
    with open(path,'rb') as f:
FileNotFoundError: [Errno 2] No such file or directory: 'YelpData.txt'
Traceback (most recent call last):
  File "/home/hduser1/Restuarant_Review/dbms.py", line 33, in initialize_yelp
    return pd.read_hdf('yelp.hdf','yelp_df')
  File "/usr/local/lib/python3.6/dist-packages/pandas/io/pytables.py", line 366, in read_hdf
    'File {path} does not exist'.format(path=path_or_buf))
FileNotFoundError: File yelp.hdf does not exist

During handling of the above exception, another exception occurred:

Traceback (most recent call last):
  File "/home/hduser1/Restuarant_Review/UpdateYelp.py", line 4, in <module>
    df = dbms.initialize_yelp()
  File "/home/hduser1/Restuarant_Review/dbms.py", line 35, in initialize_yelp
    big_list = read_data('YelpData.txt')
  File "/home/hduser1/Restuarant_Review/dbms.py", line 21, in read_data
    with open(path,'rb') as f:
FileNotFoundError: [Errno 2] No such file or directory: 'YelpData.txt'
Traceback (most recent call last):
  File "/home/hduser1/Restuarant_Review/dbms.py", line 33, in initialize_yelp
    return pd.read_hdf('yelp.hdf','yelp_df')
  File "/usr/local/lib/python3.6/dist-packages/pandas/io/pytables.py", line 366, in read_hdf
    'File {path} does not exist'.format(path=path_or_buf))
FileNotFoundError: File yelp.hdf does not exist

During handling of the above exception, another exception occurred:

Traceback (most recent call last):
  File "/home/hduser1/Restuarant_Review/UpdateYelp.py", line 4, in <module>
    df = dbms.initialize_yelp()
  File "/home/hduser1/Restuarant_Review/dbms.py", line 35, in initialize_yelp
    big_list = read_data('YelpData.txt')
  File "/home/hduser1/Restuarant_Review/dbms.py", line 21, in read_data
    with open(path,'rb') as f:
FileNotFoundError: [Errno 2] No such file or directory: 'YelpData.txt'
Traceback (most recent call last):
  File "/home/hduser1/Restuarant_Review/dbms.py", line 33, in initialize_yelp
    return pd.read_hdf('yelp.hdf','yelp_df')
  File "/usr/local/lib/python3.6/dist-packages/pandas/io/pytables.py", line 366, in read_hdf
    'File {path} does not exist'.format(path=path_or_buf))
FileNotFoundError: File yelp.hdf does not exist

During handling of the above exception, another exception occurred:

Traceback (most recent call last):
  File "/home/hduser1/Restuarant_Review/UpdateYelp.py", line 4, in <module>
    df = dbms.initialize_yelp()
  File "/home/hduser1/Restuarant_Review/dbms.py", line 35, in initialize_yelp
    big_list = read_data('YelpData.txt')
  File "/home/hduser1/Restuarant_Review/dbms.py", line 21, in read_data
    with open(path,'rb') as f:
FileNotFoundError: [Errno 2] No such file or directory: 'YelpData.txt'
Traceback (most recent call last):
  File "/home/hduser1/Restuarant_Review/dbms.py", line 33, in initialize_yelp
    return pd.read_hdf('yelp.hdf','yelp_df')
  File "/usr/local/lib/python3.6/dist-packages/pandas/io/pytables.py", line 366, in read_hdf
    'File {path} does not exist'.format(path=path_or_buf))
FileNotFoundError: File yelp.hdf does not exist

During handling of the above exception, another exception occurred:

Traceback (most recent call last):
  File "/home/hduser1/Restuarant_Review/UpdateYelp.py", line 4, in <module>
    df = dbms.initialize_yelp()
  File "/home/hduser1/Restuarant_Review/dbms.py", line 35, in initialize_yelp
    big_list = read_data('YelpData.txt')
  File "/home/hduser1/Restuarant_Review/dbms.py", line 21, in read_data
    with open(path,'rb') as f:
FileNotFoundError: [Errno 2] No such file or directory: 'YelpData.txt'
Traceback (most recent call last):
  File "/home/hduser1/Restuarant_Review/dbms.py", line 33, in initialize_yelp
    return pd.read_hdf('yelp.hdf','yelp_df')
  File "/usr/local/lib/python3.6/dist-packages/pandas/io/pytables.py", line 366, in read_hdf
    'File {path} does not exist'.format(path=path_or_buf))
FileNotFoundError: File yelp.hdf does not exist

During handling of the above exception, another exception occurred:

Traceback (most recent call last):
  File "/home/hduser1/Restuarant_Review/UpdateYelp.py", line 4, in <module>
    df = dbms.initialize_yelp()
  File "/home/hduser1/Restuarant_Review/dbms.py", line 35, in initialize_yelp
    big_list = read_data('YelpData.txt')
  File "/home/hduser1/Restuarant_Review/dbms.py", line 21, in read_data
    with open(path,'rb') as f:
FileNotFoundError: [Errno 2] No such file or directory: 'YelpData.txt'
Traceback (most recent call last):
  File "/home/hduser1/Restuarant_Review/dbms.py", line 33, in initialize_yelp
    return pd.read_hdf('yelp.hdf','yelp_df')
  File "/usr/local/lib/python3.6/dist-packages/pandas/io/pytables.py", line 366, in read_hdf
    'File {path} does not exist'.format(path=path_or_buf))
FileNotFoundError: File yelp.hdf does not exist

During handling of the above exception, another exception occurred:

Traceback (most recent call last):
  File "/home/hduser1/Restuarant_Review/UpdateYelp.py", line 4, in <module>
    df = dbms.initialize_yelp()
  File "/home/hduser1/Restuarant_Review/dbms.py", line 35, in initialize_yelp
    big_list = read_data('YelpData.txt')
  File "/home/hduser1/Restuarant_Review/dbms.py", line 21, in read_data
    with open(path,'rb') as f:
FileNotFoundError: [Errno 2] No such file or directory: 'YelpData.txt'
Traceback (most recent call last):
  File "/home/hduser1/Restuarant_Review/dbms.py", line 33, in initialize_yelp
    return pd.read_hdf('yelp.hdf','yelp_df')
  File "/usr/local/lib/python3.6/dist-packages/pandas/io/pytables.py", line 366, in read_hdf
    'File {path} does not exist'.format(path=path_or_buf))
FileNotFoundError: File yelp.hdf does not exist

During handling of the above exception, another exception occurred:

Traceback (most recent call last):
  File "/home/hduser1/Restuarant_Review/UpdateYelp.py", line 4, in <module>
    df = dbms.initialize_yelp()
  File "/home/hduser1/Restuarant_Review/dbms.py", line 35, in initialize_yelp
    big_list = read_data('YelpData.txt')
  File "/home/hduser1/Restuarant_Review/dbms.py", line 21, in read_data
    with open(path,'rb') as f:
FileNotFoundError: [Errno 2] No such file or directory: 'YelpData.txt'
Traceback (most recent call last):
  File "/home/hduser1/Restuarant_Review/dbms.py", line 33, in initialize_yelp
    return pd.read_hdf('yelp.hdf','yelp_df')
  File "/usr/local/lib/python3.6/dist-packages/pandas/io/pytables.py", line 366, in read_hdf
    'File {path} does not exist'.format(path=path_or_buf))
FileNotFoundError: File yelp.hdf does not exist

During handling of the above exception, another exception occurred:

Traceback (most recent call last):
  File "/home/hduser1/Restuarant_Review/UpdateYelp.py", line 4, in <module>
    df = dbms.initialize_yelp()
  File "/home/hduser1/Restuarant_Review/dbms.py", line 35, in initialize_yelp
    big_list = read_data('YelpData.txt')
  File "/home/hduser1/Restuarant_Review/dbms.py", line 21, in read_data
    with open(path,'rb') as f:
FileNotFoundError: [Errno 2] No such file or directory: 'YelpData.txt'
Traceback (most recent call last):
  File "/home/hduser1/Restuarant_Review/dbms.py", line 33, in initialize_yelp
    return pd.read_hdf('yelp.hdf','yelp_df')
  File "/usr/local/lib/python3.6/dist-packages/pandas/io/pytables.py", line 366, in read_hdf
    'File {path} does not exist'.format(path=path_or_buf))
FileNotFoundError: File yelp.hdf does not exist

During handling of the above exception, another exception occurred:

Traceback (most recent call last):
  File "/home/hduser1/Restuarant_Review/UpdateYelp.py", line 4, in <module>
    df = dbms.initialize_yelp()
  File "/home/hduser1/Restuarant_Review/dbms.py", line 35, in initialize_yelp
    big_list = read_data('YelpData.txt')
  File "/home/hduser1/Restuarant_Review/dbms.py", line 21, in read_data
    with open(path,'rb') as f:
FileNotFoundError: [Errno 2] No such file or directory: 'YelpData.txt'
Traceback (most recent call last):
  File "/home/hduser1/Restuarant_Review/dbms.py", line 33, in initialize_yelp
    return pd.read_hdf('yelp.hdf','yelp_df')
  File "/usr/local/lib/python3.6/dist-packages/pandas/io/pytables.py", line 366, in read_hdf
    'File {path} does not exist'.format(path=path_or_buf))
FileNotFoundError: File yelp.hdf does not exist

During handling of the above exception, another exception occurred:

Traceback (most recent call last):
  File "/home/hduser1/Restuarant_Review/UpdateYelp.py", line 4, in <module>
    df = dbms.initialize_yelp()
  File "/home/hduser1/Restuarant_Review/dbms.py", line 35, in initialize_yelp
    big_list = read_data('YelpData.txt')
  File "/home/hduser1/Restuarant_Review/dbms.py", line 21, in read_data
    with open(path,'rb') as f:
FileNotFoundError: [Errno 2] No such file or directory: 'YelpData.txt'
Traceback (most recent call last):
  File "/home/hduser1/Restuarant_Review/dbms.py", line 33, in initialize_yelp
    return pd.read_hdf('yelp.hdf','yelp_df')
  File "/usr/local/lib/python3.6/dist-packages/pandas/io/pytables.py", line 366, in read_hdf
    'File {path} does not exist'.format(path=path_or_buf))
FileNotFoundError: File yelp.hdf does not exist

During handling of the above exception, another exception occurred:

Traceback (most recent call last):
  File "/home/hduser1/Restuarant_Review/UpdateYelp.py", line 4, in <module>
    df = dbms.initialize_yelp()
  File "/home/hduser1/Restuarant_Review/dbms.py", line 35, in initialize_yelp
    big_list = read_data('YelpData.txt')
  File "/home/hduser1/Restuarant_Review/dbms.py", line 21, in read_data
    with open(path,'rb') as f:
FileNotFoundError: [Errno 2] No such file or directory: 'YelpData.txt'
Traceback (most recent call last):
  File "/home/hduser1/Restuarant_Review/dbms.py", line 33, in initialize_yelp
    return pd.read_hdf('yelp.hdf','yelp_df')
  File "/usr/local/lib/python3.6/dist-packages/pandas/io/pytables.py", line 366, in read_hdf
    'File {path} does not exist'.format(path=path_or_buf))
FileNotFoundError: File yelp.hdf does not exist

During handling of the above exception, another exception occurred:

Traceback (most recent call last):
  File "/home/hduser1/Restuarant_Review/UpdateYelp.py", line 4, in <module>
    df = dbms.initialize_yelp()
  File "/home/hduser1/Restuarant_Review/dbms.py", line 35, in initialize_yelp
    big_list = read_data('YelpData.txt')
  File "/home/hduser1/Restuarant_Review/dbms.py", line 21, in read_data
    with open(path,'rb') as f:
FileNotFoundError: [Errno 2] No such file or directory: 'YelpData.txt'
Traceback (most recent call last):
  File "/home/hduser1/Restuarant_Review/dbms.py", line 33, in initialize_yelp
    return pd.read_hdf('yelp.hdf','yelp_df')
  File "/usr/local/lib/python3.6/dist-packages/pandas/io/pytables.py", line 366, in read_hdf
    'File {path} does not exist'.format(path=path_or_buf))
FileNotFoundError: File yelp.hdf does not exist

During handling of the above exception, another exception occurred:

Traceback (most recent call last):
  File "/home/hduser1/Restuarant_Review/UpdateYelp.py", line 4, in <module>
    df = dbms.initialize_yelp()
  File "/home/hduser1/Restuarant_Review/dbms.py", line 35, in initialize_yelp
    big_list = read_data('YelpData.txt')
  File "/home/hduser1/Restuarant_Review/dbms.py", line 21, in read_data
    with open(path,'rb') as f:
FileNotFoundError: [Errno 2] No such file or directory: 'YelpData.txt'
Traceback (most recent call last):
  File "/home/hduser1/Restuarant_Review/dbms.py", line 33, in initialize_yelp
    return pd.read_hdf('yelp.hdf','yelp_df')
  File "/usr/local/lib/python3.6/dist-packages/pandas/io/pytables.py", line 366, in read_hdf
    'File {path} does not exist'.format(path=path_or_buf))
FileNotFoundError: File yelp.hdf does not exist

During handling of the above exception, another exception occurred:

Traceback (most recent call last):
  File "/home/hduser1/Restuarant_Review/UpdateYelp.py", line 4, in <module>
    df = dbms.initialize_yelp()
  File "/home/hduser1/Restuarant_Review/dbms.py", line 35, in initialize_yelp
    big_list = read_data('YelpData.txt')
  File "/home/hduser1/Restuarant_Review/dbms.py", line 21, in read_data
    with open(path,'rb') as f:
FileNotFoundError: [Errno 2] No such file or directory: 'YelpData.txt'
Traceback (most recent call last):
  File "/home/hduser1/Restuarant_Review/dbms.py", line 33, in initialize_yelp
    return pd.read_hdf('yelp.hdf','yelp_df')
  File "/usr/local/lib/python3.6/dist-packages/pandas/io/pytables.py", line 366, in read_hdf
    'File {path} does not exist'.format(path=path_or_buf))
FileNotFoundError: File yelp.hdf does not exist

During handling of the above exception, another exception occurred:

Traceback (most recent call last):
  File "/home/hduser1/Restuarant_Review/UpdateYelp.py", line 4, in <module>
    df = dbms.initialize_yelp()
  File "/home/hduser1/Restuarant_Review/dbms.py", line 35, in initialize_yelp
    big_list = read_data('YelpData.txt')
  File "/home/hduser1/Restuarant_Review/dbms.py", line 21, in read_data
    with open(path,'rb') as f:
FileNotFoundError: [Errno 2] No such file or directory: 'YelpData.txt'
Traceback (most recent call last):
  File "/home/hduser1/Restuarant_Review/dbms.py", line 33, in initialize_yelp
    return pd.read_hdf('yelp.hdf','yelp_df')
  File "/usr/local/lib/python3.6/dist-packages/pandas/io/pytables.py", line 366, in read_hdf
    'File {path} does not exist'.format(path=path_or_buf))
FileNotFoundError: File yelp.hdf does not exist

During handling of the above exception, another exception occurred:

Traceback (most recent call last):
  File "/home/hduser1/Restuarant_Review/UpdateYelp.py", line 4, in <module>
    df = dbms.initialize_yelp()
  File "/home/hduser1/Restuarant_Review/dbms.py", line 35, in initialize_yelp
    big_list = read_data('YelpData.txt')
  File "/home/hduser1/Restuarant_Review/dbms.py", line 21, in read_data
    with open(path,'rb') as f:
FileNotFoundError: [Errno 2] No such file or directory: 'YelpData.txt'
Traceback (most recent call last):
  File "/home/hduser1/Restuarant_Review/dbms.py", line 33, in initialize_yelp
    return pd.read_hdf('yelp.hdf','yelp_df')
  File "/usr/local/lib/python3.6/dist-packages/pandas/io/pytables.py", line 366, in read_hdf
    'File {path} does not exist'.format(path=path_or_buf))
FileNotFoundError: File yelp.hdf does not exist

During handling of the above exception, another exception occurred:

Traceback (most recent call last):
  File "/home/hduser1/Restuarant_Review/UpdateYelp.py", line 4, in <module>
    df = dbms.initialize_yelp()
  File "/home/hduser1/Restuarant_Review/dbms.py", line 35, in initialize_yelp
    big_list = read_data('YelpData.txt')
  File "/home/hduser1/Restuarant_Review/dbms.py", line 21, in read_data
    with open(path,'rb') as f:
FileNotFoundError: [Errno 2] No such file or directory: 'YelpData.txt'
Traceback (most recent call last):
  File "/home/hduser1/Restuarant_Review/dbms.py", line 33, in initialize_yelp
    return pd.read_hdf('yelp.hdf','yelp_df')
  File "/usr/local/lib/python3.6/dist-packages/pandas/io/pytables.py", line 366, in read_hdf
    'File {path} does not exist'.format(path=path_or_buf))
FileNotFoundError: File yelp.hdf does not exist

During handling of the above exception, another exception occurred:

Traceback (most recent call last):
  File "/home/hduser1/Restuarant_Review/UpdateYelp.py", line 4, in <module>
    df = dbms.initialize_yelp()
  File "/home/hduser1/Restuarant_Review/dbms.py", line 35, in initialize_yelp
    big_list = read_data('YelpData.txt')
  File "/home/hduser1/Restuarant_Review/dbms.py", line 21, in read_data
    with open(path,'rb') as f:
FileNotFoundError: [Errno 2] No such file or directory: 'YelpData.txt'
Traceback (most recent call last):
  File "/home/hduser1/Restuarant_Review/dbms.py", line 33, in initialize_yelp
    return pd.read_hdf('yelp.hdf','yelp_df')
  File "/usr/local/lib/python3.6/dist-packages/pandas/io/pytables.py", line 366, in read_hdf
    'File {path} does not exist'.format(path=path_or_buf))
FileNotFoundError: File yelp.hdf does not exist

During handling of the above exception, another exception occurred:

Traceback (most recent call last):
  File "/home/hduser1/Restuarant_Review/UpdateYelp.py", line 4, in <module>
    df = dbms.initialize_yelp()
  File "/home/hduser1/Restuarant_Review/dbms.py", line 35, in initialize_yelp
    big_list = read_data('YelpData.txt')
  File "/home/hduser1/Restuarant_Review/dbms.py", line 21, in read_data
    with open(path,'rb') as f:
FileNotFoundError: [Errno 2] No such file or directory: 'YelpData.txt'
Traceback (most recent call last):
  File "/home/hduser1/Restuarant_Review/dbms.py", line 33, in initialize_yelp
    return pd.read_hdf('yelp.hdf','yelp_df')
  File "/usr/local/lib/python3.6/dist-packages/pandas/io/pytables.py", line 366, in read_hdf
    'File {path} does not exist'.format(path=path_or_buf))
FileNotFoundError: File yelp.hdf does not exist

During handling of the above exception, another exception occurred:

Traceback (most recent call last):
  File "/home/hduser1/Restuarant_Review/UpdateYelp.py", line 4, in <module>
    df = dbms.initialize_yelp()
  File "/home/hduser1/Restuarant_Review/dbms.py", line 35, in initialize_yelp
    big_list = read_data('YelpData.txt')
  File "/home/hduser1/Restuarant_Review/dbms.py", line 21, in read_data
    with open(path,'rb') as f:
FileNotFoundError: [Errno 2] No such file or directory: 'YelpData.txt'
Traceback (most recent call last):
  File "/home/hduser1/Restuarant_Review/dbms.py", line 33, in initialize_yelp
    return pd.read_hdf('yelp.hdf','yelp_df')
  File "/usr/local/lib/python3.6/dist-packages/pandas/io/pytables.py", line 366, in read_hdf
    'File {path} does not exist'.format(path=path_or_buf))
FileNotFoundError: File yelp.hdf does not exist

During handling of the above exception, another exception occurred:

Traceback (most recent call last):
  File "/home/hduser1/Restuarant_Review/UpdateYelp.py", line 4, in <module>
    df = dbms.initialize_yelp()
  File "/home/hduser1/Restuarant_Review/dbms.py", line 35, in initialize_yelp
    big_list = read_data('YelpData.txt')
  File "/home/hduser1/Restuarant_Review/dbms.py", line 21, in read_data
    with open(path,'rb') as f:
FileNotFoundError: [Errno 2] No such file or directory: 'YelpData.txt'
Traceback (most recent call last):
  File "/home/hduser1/Restuarant_Review/dbms.py", line 33, in initialize_yelp
    return pd.read_hdf('yelp.hdf','yelp_df')
  File "/usr/local/lib/python3.6/dist-packages/pandas/io/pytables.py", line 366, in read_hdf
    'File {path} does not exist'.format(path=path_or_buf))
FileNotFoundError: File yelp.hdf does not exist

During handling of the above exception, another exception occurred:

Traceback (most recent call last):
  File "/home/hduser1/Restuarant_Review/UpdateYelp.py", line 4, in <module>
    df = dbms.initialize_yelp()
  File "/home/hduser1/Restuarant_Review/dbms.py", line 35, in initialize_yelp
    big_list = read_data('YelpData.txt')
  File "/home/hduser1/Restuarant_Review/dbms.py", line 21, in read_data
    with open(path,'rb') as f:
FileNotFoundError: [Errno 2] No such file or directory: 'YelpData.txt'
Traceback (most recent call last):
  File "/home/hduser1/Restuarant_Review/dbms.py", line 33, in initialize_yelp
    return pd.read_hdf('yelp.hdf','yelp_df')
  File "/usr/local/lib/python3.6/dist-packages/pandas/io/pytables.py", line 366, in read_hdf
    'File {path} does not exist'.format(path=path_or_buf))
FileNotFoundError: File yelp.hdf does not exist

During handling of the above exception, another exception occurred:

Traceback (most recent call last):
  File "/home/hduser1/Restuarant_Review/UpdateYelp.py", line 4, in <module>
    df = dbms.initialize_yelp()
  File "/home/hduser1/Restuarant_Review/dbms.py", line 35, in initialize_yelp
    big_list = read_data('YelpData.txt')
  File "/home/hduser1/Restuarant_Review/dbms.py", line 21, in read_data
    with open(path,'rb') as f:
FileNotFoundError: [Errno 2] No such file or directory: 'YelpData.txt'
Traceback (most recent call last):
  File "/home/hduser1/Restuarant_Review/dbms.py", line 33, in initialize_yelp
    return pd.read_hdf('yelp.hdf','yelp_df')
  File "/usr/local/lib/python3.6/dist-packages/pandas/io/pytables.py", line 366, in read_hdf
    'File {path} does not exist'.format(path=path_or_buf))
FileNotFoundError: File yelp.hdf does not exist

During handling of the above exception, another exception occurred:

Traceback (most recent call last):
  File "/home/hduser1/Restuarant_Review/UpdateYelp.py", line 4, in <module>
    df = dbms.initialize_yelp()
  File "/home/hduser1/Restuarant_Review/dbms.py", line 35, in initialize_yelp
    big_list = read_data('YelpData.txt')
  File "/home/hduser1/Restuarant_Review/dbms.py", line 21, in read_data
    with open(path,'rb') as f:
FileNotFoundError: [Errno 2] No such file or directory: 'YelpData.txt'
Traceback (most recent call last):
  File "/home/hduser1/Restuarant_Review/dbms.py", line 33, in initialize_yelp
    return pd.read_hdf('yelp.hdf','yelp_df')
  File "/usr/local/lib/python3.6/dist-packages/pandas/io/pytables.py", line 366, in read_hdf
    'File {path} does not exist'.format(path=path_or_buf))
FileNotFoundError: File yelp.hdf does not exist

During handling of the above exception, another exception occurred:

Traceback (most recent call last):
  File "/home/hduser1/Restuarant_Review/UpdateYelp.py", line 4, in <module>
    df = dbms.initialize_yelp()
  File "/home/hduser1/Restuarant_Review/dbms.py", line 35, in initialize_yelp
    big_list = read_data('YelpData.txt')
  File "/home/hduser1/Restuarant_Review/dbms.py", line 21, in read_data
    with open(path,'rb') as f:
FileNotFoundError: [Errno 2] No such file or directory: 'YelpData.txt'
Traceback (most recent call last):
  File "/home/hduser1/Restuarant_Review/dbms.py", line 33, in initialize_yelp
    return pd.read_hdf('yelp.hdf','yelp_df')
  File "/usr/local/lib/python3.6/dist-packages/pandas/io/pytables.py", line 366, in read_hdf
    'File {path} does not exist'.format(path=path_or_buf))
FileNotFoundError: File yelp.hdf does not exist

During handling of the above exception, another exception occurred:

Traceback (most recent call last):
  File "/home/hduser1/Restuarant_Review/UpdateYelp.py", line 4, in <module>
    df = dbms.initialize_yelp()
  File "/home/hduser1/Restuarant_Review/dbms.py", line 35, in initialize_yelp
    big_list = read_data('YelpData.txt')
  File "/home/hduser1/Restuarant_Review/dbms.py", line 21, in read_data
    with open(path,'rb') as f:
FileNotFoundError: [Errno 2] No such file or directory: 'YelpData.txt'
Traceback (most recent call last):
  File "/home/hduser1/Restuarant_Review/dbms.py", line 33, in initialize_yelp
    return pd.read_hdf('yelp.hdf','yelp_df')
  File "/usr/local/lib/python3.6/dist-packages/pandas/io/pytables.py", line 366, in read_hdf
    'File {path} does not exist'.format(path=path_or_buf))
FileNotFoundError: File yelp.hdf does not exist

During handling of the above exception, another exception occurred:

Traceback (most recent call last):
  File "/home/hduser1/Restuarant_Review/UpdateYelp.py", line 4, in <module>
    df = dbms.initialize_yelp()
  File "/home/hduser1/Restuarant_Review/dbms.py", line 35, in initialize_yelp
    big_list = read_data('YelpData.txt')
  File "/home/hduser1/Restuarant_Review/dbms.py", line 21, in read_data
    with open(path,'rb') as f:
FileNotFoundError: [Errno 2] No such file or directory: 'YelpData.txt'
Traceback (most recent call last):
  File "/home/hduser1/Restuarant_Review/dbms.py", line 33, in initialize_yelp
    return pd.read_hdf('yelp.hdf','yelp_df')
  File "/usr/local/lib/python3.6/dist-packages/pandas/io/pytables.py", line 366, in read_hdf
    'File {path} does not exist'.format(path=path_or_buf))
FileNotFoundError: File yelp.hdf does not exist

During handling of the above exception, another exception occurred:

Traceback (most recent call last):
  File "/home/hduser1/Restuarant_Review/UpdateYelp.py", line 4, in <module>
    df = dbms.initialize_yelp()
  File "/home/hduser1/Restuarant_Review/dbms.py", line 35, in initialize_yelp
    big_list = read_data('YelpData.txt')
  File "/home/hduser1/Restuarant_Review/dbms.py", line 21, in read_data
    with open(path,'rb') as f:
FileNotFoundError: [Errno 2] No such file or directory: 'YelpData.txt'
Traceback (most recent call last):
  File "/home/hduser1/Restuarant_Review/dbms.py", line 33, in initialize_yelp
    return pd.read_hdf('yelp.hdf','yelp_df')
  File "/usr/local/lib/python3.6/dist-packages/pandas/io/pytables.py", line 366, in read_hdf
    'File {path} does not exist'.format(path=path_or_buf))
FileNotFoundError: File yelp.hdf does not exist

During handling of the above exception, another exception occurred:

Traceback (most recent call last):
  File "/home/hduser1/Restuarant_Review/UpdateYelp.py", line 4, in <module>
    df = dbms.initialize_yelp()
  File "/home/hduser1/Restuarant_Review/dbms.py", line 35, in initialize_yelp
    big_list = read_data('YelpData.txt')
  File "/home/hduser1/Restuarant_Review/dbms.py", line 21, in read_data
    with open(path,'rb') as f:
FileNotFoundError: [Errno 2] No such file or directory: 'YelpData.txt'
Traceback (most recent call last):
  File "/home/hduser1/Restuarant_Review/dbms.py", line 33, in initialize_yelp
    return pd.read_hdf('yelp.hdf','yelp_df')
  File "/usr/local/lib/python3.6/dist-packages/pandas/io/pytables.py", line 366, in read_hdf
    'File {path} does not exist'.format(path=path_or_buf))
FileNotFoundError: File yelp.hdf does not exist

During handling of the above exception, another exception occurred:

Traceback (most recent call last):
  File "/home/hduser1/Restuarant_Review/UpdateYelp.py", line 4, in <module>
    df = dbms.initialize_yelp()
  File "/home/hduser1/Restuarant_Review/dbms.py", line 35, in initialize_yelp
    big_list = read_data('YelpData.txt')
  File "/home/hduser1/Restuarant_Review/dbms.py", line 21, in read_data
    with open(path,'rb') as f:
FileNotFoundError: [Errno 2] No such file or directory: 'YelpData.txt'
Traceback (most recent call last):
  File "/home/hduser1/Restuarant_Review/dbms.py", line 33, in initialize_yelp
    return pd.read_hdf('yelp.hdf','yelp_df')
  File "/usr/local/lib/python3.6/dist-packages/pandas/io/pytables.py", line 366, in read_hdf
    'File {path} does not exist'.format(path=path_or_buf))
FileNotFoundError: File yelp.hdf does not exist

During handling of the above exception, another exception occurred:

Traceback (most recent call last):
  File "/home/hduser1/Restuarant_Review/UpdateYelp.py", line 4, in <module>
    df = dbms.initialize_yelp()
  File "/home/hduser1/Restuarant_Review/dbms.py", line 35, in initialize_yelp
    big_list = read_data('YelpData.txt')
  File "/home/hduser1/Restuarant_Review/dbms.py", line 21, in read_data
    with open(path,'rb') as f:
FileNotFoundError: [Errno 2] No such file or directory: 'YelpData.txt'
Traceback (most recent call last):
  File "/home/hduser1/Restuarant_Review/dbms.py", line 33, in initialize_yelp
    return pd.read_hdf('yelp.hdf','yelp_df')
  File "/usr/local/lib/python3.6/dist-packages/pandas/io/pytables.py", line 366, in read_hdf
    'File {path} does not exist'.format(path=path_or_buf))
FileNotFoundError: File yelp.hdf does not exist

During handling of the above exception, another exception occurred:

Traceback (most recent call last):
  File "/home/hduser1/Restuarant_Review/UpdateYelp.py", line 4, in <module>
    df = dbms.initialize_yelp()
  File "/home/hduser1/Restuarant_Review/dbms.py", line 35, in initialize_yelp
    big_list = read_data('YelpData.txt')
  File "/home/hduser1/Restuarant_Review/dbms.py", line 21, in read_data
    with open(path,'rb') as f:
FileNotFoundError: [Errno 2] No such file or directory: 'YelpData.txt'
Traceback (most recent call last):
  File "/home/hduser1/Restuarant_Review/dbms.py", line 33, in initialize_yelp
    return pd.read_hdf('yelp.hdf','yelp_df')
  File "/usr/local/lib/python3.6/dist-packages/pandas/io/pytables.py", line 366, in read_hdf
    'File {path} does not exist'.format(path=path_or_buf))
FileNotFoundError: File yelp.hdf does not exist

During handling of the above exception, another exception occurred:

Traceback (most recent call last):
  File "/home/hduser1/Restuarant_Review/UpdateYelp.py", line 4, in <module>
    df = dbms.initialize_yelp()
  File "/home/hduser1/Restuarant_Review/dbms.py", line 35, in initialize_yelp
    big_list = read_data('YelpData.txt')
  File "/home/hduser1/Restuarant_Review/dbms.py", line 21, in read_data
    with open(path,'rb') as f:
FileNotFoundError: [Errno 2] No such file or directory: 'YelpData.txt'
Traceback (most recent call last):
  File "/home/hduser1/Restuarant_Review/dbms.py", line 33, in initialize_yelp
    return pd.read_hdf('yelp.hdf','yelp_df')
  File "/usr/local/lib/python3.6/dist-packages/pandas/io/pytables.py", line 366, in read_hdf
    'File {path} does not exist'.format(path=path_or_buf))
FileNotFoundError: File yelp.hdf does not exist

During handling of the above exception, another exception occurred:

Traceback (most recent call last):
  File "/home/hduser1/Restuarant_Review/UpdateYelp.py", line 4, in <module>
    df = dbms.initialize_yelp()
  File "/home/hduser1/Restuarant_Review/dbms.py", line 35, in initialize_yelp
    big_list = read_data('YelpData.txt')
  File "/home/hduser1/Restuarant_Review/dbms.py", line 21, in read_data
    with open(path,'rb') as f:
FileNotFoundError: [Errno 2] No such file or directory: 'YelpData.txt'
Traceback (most recent call last):
  File "/home/hduser1/Restuarant_Review/dbms.py", line 33, in initialize_yelp
    return pd.read_hdf('yelp.hdf','yelp_df')
  File "/usr/local/lib/python3.6/dist-packages/pandas/io/pytables.py", line 366, in read_hdf
    'File {path} does not exist'.format(path=path_or_buf))
FileNotFoundError: File yelp.hdf does not exist

During handling of the above exception, another exception occurred:

Traceback (most recent call last):
  File "/home/hduser1/Restuarant_Review/UpdateYelp.py", line 4, in <module>
    df = dbms.initialize_yelp()
  File "/home/hduser1/Restuarant_Review/dbms.py", line 35, in initialize_yelp
    big_list = read_data('YelpData.txt')
  File "/home/hduser1/Restuarant_Review/dbms.py", line 21, in read_data
    with open(path,'rb') as f:
FileNotFoundError: [Errno 2] No such file or directory: 'YelpData.txt'
Traceback (most recent call last):
  File "/home/hduser1/Restuarant_Review/dbms.py", line 33, in initialize_yelp
    return pd.read_hdf('yelp.hdf','yelp_df')
  File "/usr/local/lib/python3.6/dist-packages/pandas/io/pytables.py", line 366, in read_hdf
    'File {path} does not exist'.format(path=path_or_buf))
FileNotFoundError: File yelp.hdf does not exist

During handling of the above exception, another exception occurred:

Traceback (most recent call last):
  File "/home/hduser1/Restuarant_Review/UpdateYelp.py", line 4, in <module>
    df = dbms.initialize_yelp()
  File "/home/hduser1/Restuarant_Review/dbms.py", line 35, in initialize_yelp
    big_list = read_data('YelpData.txt')
  File "/home/hduser1/Restuarant_Review/dbms.py", line 21, in read_data
    with open(path,'rb') as f:
FileNotFoundError: [Errno 2] No such file or directory: 'YelpData.txt'
Traceback (most recent call last):
  File "/home/hduser1/Restuarant_Review/dbms.py", line 33, in initialize_yelp
    return pd.read_hdf('yelp.hdf','yelp_df')
  File "/usr/local/lib/python3.6/dist-packages/pandas/io/pytables.py", line 366, in read_hdf
    'File {path} does not exist'.format(path=path_or_buf))
FileNotFoundError: File yelp.hdf does not exist

During handling of the above exception, another exception occurred:

Traceback (most recent call last):
  File "/home/hduser1/Restuarant_Review/UpdateYelp.py", line 4, in <module>
    df = dbms.initialize_yelp()
  File "/home/hduser1/Restuarant_Review/dbms.py", line 35, in initialize_yelp
    big_list = read_data('YelpData.txt')
  File "/home/hduser1/Restuarant_Review/dbms.py", line 21, in read_data
    with open(path,'rb') as f:
FileNotFoundError: [Errno 2] No such file or directory: 'YelpData.txt'
Traceback (most recent call last):
  File "/home/hduser1/Restuarant_Review/dbms.py", line 33, in initialize_yelp
    return pd.read_hdf('yelp.hdf','yelp_df')
  File "/usr/local/lib/python3.6/dist-packages/pandas/io/pytables.py", line 366, in read_hdf
    'File {path} does not exist'.format(path=path_or_buf))
FileNotFoundError: File yelp.hdf does not exist

During handling of the above exception, another exception occurred:

Traceback (most recent call last):
  File "/home/hduser1/Restuarant_Review/UpdateYelp.py", line 4, in <module>
    df = dbms.initialize_yelp()
  File "/home/hduser1/Restuarant_Review/dbms.py", line 35, in initialize_yelp
    big_list = read_data('YelpData.txt')
  File "/home/hduser1/Restuarant_Review/dbms.py", line 21, in read_data
    with open(path,'rb') as f:
FileNotFoundError: [Errno 2] No such file or directory: 'YelpData.txt'
Traceback (most recent call last):
  File "/home/hduser1/Restuarant_Review/dbms.py", line 33, in initialize_yelp
    return pd.read_hdf('yelp.hdf','yelp_df')
  File "/usr/local/lib/python3.6/dist-packages/pandas/io/pytables.py", line 366, in read_hdf
    'File {path} does not exist'.format(path=path_or_buf))
FileNotFoundError: File yelp.hdf does not exist

During handling of the above exception, another exception occurred:

Traceback (most recent call last):
  File "/home/hduser1/Restuarant_Review/UpdateYelp.py", line 4, in <module>
    df = dbms.initialize_yelp()
  File "/home/hduser1/Restuarant_Review/dbms.py", line 35, in initialize_yelp
    big_list = read_data('YelpData.txt')
  File "/home/hduser1/Restuarant_Review/dbms.py", line 21, in read_data
    with open(path,'rb') as f:
FileNotFoundError: [Errno 2] No such file or directory: 'YelpData.txt'
