Updating at: 2019-05-04 13:00:12.529250
Traceback (most recent call last):
  File "/home/hduser1/Restuarant_Review/UpdateZomato.py", line 7, in <module>
    update_zomato(zomato_df)
  File "/home/hduser1/Restuarant_Review/KafkaTopics.py", line 30, in update_zomato
    Zomato_Scrapper.scrape_all_review_ID()
  File "/home/hduser1/Restuarant_Review/Zomato_Scrapper.py", line 116, in scrape_all_review_ID
    recent_reviews[rest] = scrape_reviews_from_restaurant_id(rest)
  File "/home/hduser1/Restuarant_Review/Zomato_Scrapper.py", line 66, in scrape_reviews_from_restaurant_id
    user_reviews = json.loads(response_json.text)["user_reviews"]
KeyError: 'user_reviews'
Closing remaining open files:/home/hduser1/Restuarant_Review/zomato.hdf...done
Updating at: 2019-05-04 13:01:14.479766
Traceback (most recent call last):
  File "/home/hduser1/Restuarant_Review/UpdateZomato.py", line 7, in <module>
    update_zomato(zomato_df)
  File "/home/hduser1/Restuarant_Review/KafkaTopics.py", line 30, in update_zomato
    Zomato_Scrapper.scrape_all_review_ID()
  File "/home/hduser1/Restuarant_Review/Zomato_Scrapper.py", line 116, in scrape_all_review_ID
    recent_reviews[rest] = scrape_reviews_from_restaurant_id(rest)
  File "/home/hduser1/Restuarant_Review/Zomato_Scrapper.py", line 66, in scrape_reviews_from_restaurant_id
    user_reviews = json.loads(response_json.text)["user_reviews"]
KeyError: 'user_reviews'
Closing remaining open files:/home/hduser1/Restuarant_Review/zomato.hdf...done
Updating at: 2019-05-04 13:02:15.437438
Traceback (most recent call last):
  File "/home/hduser1/Restuarant_Review/UpdateZomato.py", line 7, in <module>
    update_zomato(zomato_df)
  File "/home/hduser1/Restuarant_Review/KafkaTopics.py", line 30, in update_zomato
    Zomato_Scrapper.scrape_all_review_ID()
  File "/home/hduser1/Restuarant_Review/Zomato_Scrapper.py", line 116, in scrape_all_review_ID
    recent_reviews[rest] = scrape_reviews_from_restaurant_id(rest)
  File "/home/hduser1/Restuarant_Review/Zomato_Scrapper.py", line 66, in scrape_reviews_from_restaurant_id
    user_reviews = json.loads(response_json.text)["user_reviews"]
KeyError: 'user_reviews'
Closing remaining open files:/home/hduser1/Restuarant_Review/zomato.hdf...done
Updating at: 2019-05-04 13:03:15.308524
Traceback (most recent call last):
  File "/home/hduser1/Restuarant_Review/UpdateZomato.py", line 7, in <module>
    update_zomato(zomato_df)
  File "/home/hduser1/Restuarant_Review/KafkaTopics.py", line 30, in update_zomato
    Zomato_Scrapper.scrape_all_review_ID()
  File "/home/hduser1/Restuarant_Review/Zomato_Scrapper.py", line 116, in scrape_all_review_ID
    recent_reviews[rest] = scrape_reviews_from_restaurant_id(rest)
  File "/home/hduser1/Restuarant_Review/Zomato_Scrapper.py", line 66, in scrape_reviews_from_restaurant_id
    user_reviews = json.loads(response_json.text)["user_reviews"]
KeyError: 'user_reviews'
Closing remaining open files:/home/hduser1/Restuarant_Review/zomato.hdf...done
Updating at: 2019-05-04 13:04:14.980634
Traceback (most recent call last):
  File "/home/hduser1/Restuarant_Review/UpdateZomato.py", line 7, in <module>
    update_zomato(zomato_df)
  File "/home/hduser1/Restuarant_Review/KafkaTopics.py", line 30, in update_zomato
    Zomato_Scrapper.scrape_all_review_ID()
  File "/home/hduser1/Restuarant_Review/Zomato_Scrapper.py", line 116, in scrape_all_review_ID
    recent_reviews[rest] = scrape_reviews_from_restaurant_id(rest)
  File "/home/hduser1/Restuarant_Review/Zomato_Scrapper.py", line 66, in scrape_reviews_from_restaurant_id
    user_reviews = json.loads(response_json.text)["user_reviews"]
KeyError: 'user_reviews'
Closing remaining open files:/home/hduser1/Restuarant_Review/zomato.hdf...done
Updating at: 2019-05-04 13:05:16.525318
Traceback (most recent call last):
  File "/home/hduser1/Restuarant_Review/UpdateZomato.py", line 7, in <module>
    update_zomato(zomato_df)
  File "/home/hduser1/Restuarant_Review/KafkaTopics.py", line 30, in update_zomato
    Zomato_Scrapper.scrape_all_review_ID()
  File "/home/hduser1/Restuarant_Review/Zomato_Scrapper.py", line 116, in scrape_all_review_ID
    recent_reviews[rest] = scrape_reviews_from_restaurant_id(rest)
  File "/home/hduser1/Restuarant_Review/Zomato_Scrapper.py", line 66, in scrape_reviews_from_restaurant_id
    user_reviews = json.loads(response_json.text)["user_reviews"]
KeyError: 'user_reviews'
Closing remaining open files:/home/hduser1/Restuarant_Review/zomato.hdf...done
